<sdf version='1.7'>
  <world name='default'>
    <light name='sun' type='directional'>
      <cast_shadows>1</cast_shadows>
      <pose>0 0 10 0 -0 0</pose>
      <diffuse>0.8 0.8 0.8 1</diffuse>
      <specular>0.2 0.2 0.2 1</specular>
      <attenuation>
        <range>1000</range>
        <constant>0.9</constant>
        <linear>0.01</linear>
        <quadratic>0.001</quadratic>
      </attenuation>
      <direction>-0.5 0.1 -0.9</direction>
      <spot>
        <inner_angle>0</inner_angle>
        <outer_angle>0</outer_angle>
        <falloff>0</falloff>
      </spot>
    </light>
    <model name='ground_plane'>
      <static>1</static>
      <link name='link'>
        <collision name='collision'>
          <geometry>
            <plane>
              <normal>0 0 1</normal>
              <size>100 100</size>
            </plane>
          </geometry>
          <surface>
            <contact>
              <collide_bitmask>65535</collide_bitmask>
              <ode/>
            </contact>
            <friction>
              <ode>
                <mu>100</mu>
                <mu2>50</mu2>
              </ode>
              <torsional>
                <ode/>
              </torsional>
            </friction>
            <bounce/>
          </surface>
          <max_contacts>10</max_contacts>
        </collision>
        <visual name='visual'>
          <cast_shadows>0</cast_shadows>
          <geometry>
            <plane>
              <normal>0 0 1</normal>
              <size>100 100</size>
            </plane>
          </geometry>
          <material>
            <script>
              <uri>file://media/materials/scripts/gazebo.material</uri>
              <name>Gazebo/Grey</name>
            </script>
          </material>
        </visual>
        <self_collide>0</self_collide>
        <enable_wind>0</enable_wind>
        <kinematic>0</kinematic>
      </link>
    </model>
    <gravity>0 0 -9.8</gravity>
    <magnetic_field>6e-06 2.3e-05 -4.2e-05</magnetic_field>
    <atmosphere type='adiabatic'/>
    <physics type='ode'>
      <max_step_size>0.001</max_step_size>
      <real_time_factor>1</real_time_factor>
      <real_time_update_rate>1000</real_time_update_rate>
    </physics>
    <scene>
      <ambient>0.4 0.4 0.4 1</ambient>
      <background>0.7 0.7 0.7 1</background>
      <shadows>1</shadows>
    </scene>
    <wind/>
    <spherical_coordinates>
      <surface_model>EARTH_WGS84</surface_model>
      <latitude_deg>0</latitude_deg>
      <longitude_deg>0</longitude_deg>
      <elevation>0</elevation>
      <heading_deg>0</heading_deg>
    </spherical_coordinates>
    <state world_name='default'>
      <sim_time>1150 637000000</sim_time>
      <real_time>57 771481793</real_time>
      <wall_time>1650919619 666299657</wall_time>
      <iterations>32420</iterations>
      <model name='basic_mobile_bot'>
        <pose>-0.222893 -0.081021 8e-06 -3e-06 3e-06 0.052564</pose>
        <scale>1 1 1</scale>
        <link name='camera_depth_frame'>
          <pose>-5.67632 -3.50761 -5.12026e+06 -1.5708 -2e-06 -1.94009</pose>
          <velocity>0 0 -10017.9 0 -0 0</velocity>
          <acceleration>0 0 -9.8 0 -0 0</acceleration>
          <wrench>0 0 -9.8 0 -0 0</wrench>
        </link>
        <link name='cameralink'>
          <pose>0.026763 -0.067884 0.400007 -3e-06 3e-06 0.052564</pose>
          <velocity>0.000295 0.00017 0.003127 0.000185 0.00024 2.8e-05</velocity>
          <acceleration>-0.928559 -0.91586 5.79289 -0.144889 -0.153603 -3.1207</acceleration>
          <wrench>-0.928559 -0.91586 5.79289 0 -0 0</wrench>
        </link>
        <link name='chassis'>
          <pose>-0.222892 -0.08102 0.250008 -3e-06 3e-06 0.052564</pose>
          <velocity>0.00026 0.000173 0.003202 0.000186 0.00023 9e-06</velocity>
          <acceleration>-0.482649 -0.499149 5.02357 -0.132908 -0.145981 -3.14113</acceleration>
          <wrench>-0.482649 -0.499149 5.02357 0 -0 0</wrench>
        </link>
        <link name='front_left_wheel'>
          <pose>0.034546 0.202898 0.165006 -1.57069 0.461012 0.052514</pose>
          <velocity>4.6e-05 -2.2e-05 0.003257 0.000154 0.000259 0</velocity>
          <acceleration>-0.41898 -0.466858 6.72723 -0.164077 -0.175933 3.13283</acceleration>
          <wrench>-0.41898 -0.466858 6.72723 0 -0 0</wrench>
        </link>
        <link name='front_right_wheel'>
          <pose>0.062918 -0.336356 0.165007 1.57069 0.446714 -3.08917</pose>
          <velocity>0.000323 0.000289 0.003007 0.000196 0.000244 2.6e-05</velocity>
          <acceleration>-0.156691 -0.149602 4.98208 -0.116329 -0.161357 -3.12432</acceleration>
          <wrench>-0.156691 -0.149602 4.98208 0 -0 0</wrench>
        </link>
        <link name='gps_link'>
          <pose>-5.90947 -3.41737 -5.12026e+06 -2e-06 1e-06 -0.36929</pose>
          <velocity>0 0 -10017.9 0 -0 0</velocity>
          <acceleration>0 0 -9.8 0 -0 0</acceleration>
          <wrench>0 0 -9.8 0 -0 0</wrench>
        </link>
        <link name='imu_link'>
          <pose>-5.90947 -3.41737 -5.12026e+06 -2e-06 1e-06 -0.36929</pose>
          <velocity>0 0 -10017.9 0 -0 0</velocity>
          <acceleration>0 0 -9.8 0 -0 0</acceleration>
          <wrench>0 0 -9.8 0 -0 0</wrench>
        </link>
        <link name='rear_left_wheel'>
          <pose>-0.508702 0.174316 0.165008 0.035243 1.5707 1.65851</pose>
          <velocity>0.000269 0.000271 0.003218 0.000208 0.000244 4.2e-05</velocity>
          <acceleration>-0.188343 -0.17858 4.87901 -0.121317 -0.151343 -3.10896</acceleration>
          <wrench>-0.188343 -0.17858 4.87901 0 -0 0</wrench>
        </link>
        <link name='rear_right_wheel'>
          <pose>-0.480331 -0.364938 0.165009 0.035417 1.5707 1.65868</pose>
          <velocity>0.000282 0.000204 0.003237 0.000194 0.00025 4.7e-05</velocity>
          <acceleration>-0.24855 -0.259052 3.34401 -0.137396 -0.167043 -3.10572</acceleration>
          <wrench>-0.24855 -0.259052 3.34401 0 -0 0</wrench>
        </link>
      </model>
      <model name='ground_plane'>
        <pose>0 0 0 0 -0 0</pose>
        <scale>1 1 1</scale>
        <link name='link'>
          <pose>0 0 0 0 -0 0</pose>
          <velocity>0 0 0 0 -0 0</velocity>
          <acceleration>0 0 0 0 -0 0</acceleration>
          <wrench>0 0 0 0 -0 0</wrench>
        </link>
      </model>
      <model name='husky'>
        <pose>4.17129 0.325474 0.142752 -1e-06 -6e-06 -2.25607</pose>
        <scale>1 1 1</scale>
        <link name='back_left_wheel'>
          <pose>4.55434 0.34301 0.177751 -0.00058 -1.54723 -2.25549</pose>
          <velocity>-0.002611 -0.001485 8e-05 0.008133 -0.014676 0.000464</velocity>
          <acceleration>-0.247733 -0.036207 -8.07768 0.352182 -1.08637 3.08507</acceleration>
          <wrench>-0.65295 -0.095431 -21.2903 0 -0 0</wrench>
        </link>
        <link name='back_right_wheel'>
          <pose>4.11228 0.704353 0.177751 3.5e-05 -0.964235 -2.25609</pose>
          <velocity>-0.003424 -0.001459 -0.00318 0.003975 -0.003812 -0.000712</velocity>
          <acceleration>-2.21789 -0.786419 -4.31238 0.039817 0.048785 0.271114</acceleration>
          <wrench>-5.84569 -2.07276 -11.3661 0 -0 0</wrench>
        </link>
        <link name='base_link'>
          <pose>4.17129 0.325474 0.142752 -1e-06 -6e-06 -2.25607</pose>
          <velocity>-0.002742 -0.001972 8e-05 -0.008392 -0.000351 0.000892</velocity>
          <acceleration>0.512212 0.081352 -5.02283 1.786 -0.024012 -1.85261</acceleration>
          <wrench>17.3409 2.75418 -170.048 0 -0 0</wrench>
        </link>
        <link name='front_left_wheel'>
          <pose>4.2303 -0.053405 0.177754 -3.14133 1.55439 0.885791</pose>
          <velocity>-0.002214 -0.00181 0.003245 0.007338 -0.01443 0.000431</velocity>
          <acceleration>0.768732 -0.825146 -4.52626 1.04054 1.27293 3.03765</acceleration>
          <wrench>2.02615 -2.17484 -11.9299 0 -0 0</wrench>
        </link>
        <link name='front_right_wheel'>
          <pose>3.78825 0.307938 0.177754 4.5e-05 1.04179 -2.25603</pose>
          <velocity>-0.002775 -0.001966 0.000126 0.011464 -0.015688 0.00103</velocity>
          <acceleration>-0.893807 -1.79703 -0.679351 -1.87323 0.817832 -2.29955</acceleration>
          <wrench>-2.35581 -4.73644 -1.79056 0 -0 0</wrench>
        </link>
      </model>
      <model name='prius_hybrid'>
        <pose>5.75083 -4.27847 0.011641 -2e-06 -0 2.2247</pose>
        <scale>1 1 1</scale>
        <link name='chassis'>
          <pose>5.75083 -4.27847 0.011641 -2e-06 -0 2.2247</pose>
          <velocity>-7e-06 4e-06 2.1e-05 2e-06 -3e-06 4e-06</velocity>
          <acceleration>0 0 0 -0.000322 -0.000168 0</acceleration>
          <wrench>1.9e-05 5e-06 0 0 -0 0</wrench>
        </link>
        <link name='front_left_wheel'>
          <pose>6.40767 -2.81756 0.311646 -0.029255 0.056918 2.93395</pose>
          <velocity>-1.4e-05 6e-06 3.2e-05 -1.9e-05 -4.3e-05 0.000709</velocity>
          <acceleration>0 0 -0 0 0 -1e-06</acceleration>
          <wrench>0 0 -0 0 -0 0</wrench>
        </link>
        <link name='front_right_wheel'>
          <pose>7.33227 -4.024 0.311646 -0.008789 0.049199 2.82246</pose>
          <velocity>-9e-06 1e-05 3.1e-05 -3.2e-05 -2.6e-05 0.00049</velocity>
          <acceleration>0 -0 0 0 0 -1e-06</acceleration>
          <wrench>0 -0 0 0 -0 0</wrench>
        </link>
        <link name='rear_axle'>
          <pose>4.59994 -5.16049 0.311637 -2e-06 -4e-06 2.2247</pose>
          <velocity>-4e-06 -2e-06 1.5e-05 6e-06 -1e-06 4e-06</velocity>
          <acceleration>0 0 -0 -0.351132 0.436356 2e-06</acceleration>
          <wrench>0 0 -0 0 -0 0</wrench>
        </link>
        <link name='rear_left_wheel'>
          <pose>4.12183 -4.53663 0.311647 -0.053776 -3e-06 2.2247</pose>
          <velocity>-6e-06 -4e-06 2.5e-05 1.5e-05 -1.9e-05 4e-06</velocity>
          <acceleration>0 0 -0 0 -0 0</acceleration>
          <wrench>0 0 -0 0 -0 0</wrench>
        </link>
        <link name='rear_right_wheel'>
          <pose>5.07806 -5.78435 0.311647 -0.029001 8e-06 2.2247</pose>
          <velocity>-2e-06 0 2.5e-05 1e-06 -5e-06 4e-06</velocity>
          <acceleration>0 0 -0 0 -0 0</acceleration>
          <wrench>0 0 -0 0 -0 0</wrench>
        </link>
        <link name='steering_wheel'>
          <pose>6.03237 -3.61451 0.997957 -8.3e-05 1.30202 -2.48769</pose>
          <velocity>-1.2e-05 3e-06 2.3e-05 2e-06 -2e-06 4e-06</velocity>
          <acceleration>0 0 -0 0 -0 0</acceleration>
          <wrench>0 0 -0 0 -0 0</wrench>
        </link>
      </model>
      <model name='suv'>
        <pose>6.9927 5.14321 0 0 0 -0.663086</pose>
        <scale>1 1 1</scale>
        <link name='link'>
          <pose>6.9927 5.14321 0 0 0 -0.663086</pose>
          <velocity>0 0 0 0 -0 0</velocity>
          <acceleration>0 0 0 0 -0 0</acceleration>
          <wrench>0 0 0 0 -0 0</wrench>
        </link>
      </model>
      <model name='youbot'>
        <pose>4.12503 -0.766045 0.083974 1.6e-05 2.6e-05 0.979743</pose>
        <scale>1 1 1</scale>
        <link name='arm_link_0'>
          <pose>4.20472 -0.647304 0.129968 2.1e-05 2.7e-05 0.979742</pose>
          <velocity>0.000545 -0.000515 0.00081 0.006099 0.003176 -0.001519</velocity>
          <acceleration>0.080893 -0.291156 -0.305808 -2.61874 0.39468 -1.881</acceleration>
          <wrench>0.068355 -0.246026 -0.258408 0 -0 0</wrench>
        </link>
        <link name='arm_link_1'>
          <pose>4.21809 -0.627374 0.225967 -2.8e-05 -3.3e-05 -2.33645</pose>
          <velocity>0.000803 -0.000873 0.000822 0.008979 0.004269 0.004457</velocity>
          <acceleration>0.021285 -0.342337 -0.404192 1.91209 0.29491 0.368359</acceleration>
          <wrench>0.05134 -0.825717 -0.974912 0 -0 0</wrench>
        </link>
        <link name='arm_link_2'>
          <pose>4.19522 -0.651165 0.244967 -0.000104 -1.1345 -2.33638</pose>
          <velocity>0.000922 -0.001354 0.000443 0.003568 0.0142 -0.00804</velocity>
          <acceleration>0.657706 -0.193435 -0.474433 2.68992 -1.16567 -0.478265</acceleration>
          <wrench>0.75965 -0.223418 -0.54797 0 -0 0</wrench>
        </link>
        <link name='arm_link_3'>
          <pose>4.29258 -0.549889 0.310449 0.000435 1.41373 -2.33604</pose>
          <velocity>0.000754 -0.00143 -0.003607 -0.019354 0.017315 -0.005442</velocity>
          <acceleration>-0.806834 -1.38505 -3.60048 2.03536 1.20379 1.1702</acceleration>
          <wrench>-0.753583 -1.29364 -3.36285 0 -0 0</wrench>
        </link>
        <link name='arm_link_4'>
          <pose>4.20017 -0.646013 0.331563 0.000103 -0.375206 -2.33651</pose>
          <velocity>0.000693 -0.000595 -0.001655 -0.008257 0.001211 -0.006198</velocity>
          <acceleration>0.310331 1.40273 7.09472 2.39979 -0.599798 -2.58622</acceleration>
          <wrench>0.272161 1.23019 6.22207 0 -0 0</wrench>
        </link>
        <link name='arm_link_5'>
          <pose>4.23447 -0.610321 0.451787 -0.303876 0.22358 -0.150006</pose>
          <velocity>0.00022 0.000471 -0.002323 0.004166 0.009668 -0.007674</velocity>
          <acceleration>-2.15796 4.54657 5.03094 -0.212401 -1.30689 0.725543</acceleration>
          <wrench>-0.541649 1.14119 1.26277 0 -0 0</wrench>
        </link>
        <link name='base_footprint'>
          <pose>4.12503 -0.766045 0.083974 1.6e-05 2.6e-05 0.979743</pose>
          <velocity>0.000365 -0.000213 0.000743 0.00334 0.002542 -0.000462</velocity>
          <acceleration>0.141661 -0.15204 -0.084 0.223915 -0.324912 0.156746</acceleration>
          <wrench>0.014166 -0.015204 -0.0084 0 -0 0</wrench>
        </link>
        <link name='base_laser_front_link'>
          <pose>4.2922 -0.516939 0.053966 1.6e-05 2.6e-05 0.979743</pose>
          <velocity>0.000402 -0.000183 0.001156 0.003334 0.002537 -0.000433</velocity>
          <acceleration>0.095501 -0.123282 0.039633 0.220598 -0.330772 0.202398</acceleration>
          <wrench>0.01528 -0.019725 0.006341 0 -0 0</wrench>
        </link>
        <link name='base_link'>
          <pose>4.12503 -0.766045 0.083974 1.6e-05 2.6e-05 0.979743</pose>
          <velocity>0.000365 -0.000212 0.000747 0.003342 0.002543 -0.000459</velocity>
          <acceleration>0.12555 -0.162377 -0.081385 0.219346 -0.386708 0.305765</acceleration>
          <wrench>2.7621 -3.57228 -1.79048 0 -0 0</wrench>
        </link>
        <link name='caster_link_bl'>
          <pose>3.86678 -0.867324 0.05 1.6e-05 2.6e-05 0.97992</pose>
          <velocity>0.000263 5.8e-05 0.000165 0.003323 0.00252 -0.000125</velocity>
          <acceleration>0.074215 -0.055759 0.003659 0.147235 -0.382685 0.051952</acceleration>
          <wrench>0.007421 -0.005576 0.000366 0 -0 0</wrench>
        </link>
        <link name='caster_link_br'>
          <pose>4.12918 -1.04341 0.049996 1.6e-05 2.6e-05 0.981505</pose>
          <velocity>0.000157 -0.000105 0.000389 0.003337 0.00255 -0.000296</velocity>
          <acceleration>0.097723 -0.021294 0.017719 0.20158 -0.3443 0.057005</acceleration>
          <wrench>0.009772 -0.002129 0.001772 0 -0 0</wrench>
        </link>
        <link name='caster_link_fl'>
          <pose>4.12088 -0.488682 0.05 1.6e-05 2.6e-05 0.986299</pose>
          <velocity>0.000334 1.1e-05 0.000298 0.003346 0.002558 -0.00014</velocity>
          <acceleration>0.046668 -0.038618 -0.027348 0.136594 -0.408048 0.049695</acceleration>
          <wrench>0.004667 -0.003862 -0.002735 0 -0 0</wrench>
        </link>
        <link name='caster_link_fr'>
          <pose>4.38328 -0.664768 0.049996 1.6e-05 2.6e-05 0.988498</pose>
          <velocity>0.00023 -0.000151 0.000521 0.00337 0.002583 -0.000274</velocity>
          <acceleration>0.072903 0.000389 -0.011812 0.192183 -0.367139 0.053416</acceleration>
          <wrench>0.00729 3.9e-05 -0.001181 0 -0 0</wrench>
        </link>
        <link name='gripper_finger_link_l'>
          <pose>4.25151 -0.580157 0.48801 0.303878 -0.223581 2.99159</pose>
          <velocity>0.00037 4.6e-05 -0.002155 0.002756 0.007963 -0.003504</velocity>
          <acceleration>-2.81395 4.86849 5.17375 1.03163 0.218303 -2.61774</acceleration>
          <wrench>-0.02814 0.048685 0.051737 0 -0 0</wrench>
        </link>
        <link name='gripper_finger_link_r'>
          <pose>4.24939 -0.606375 0.496033 -0.303878 0.22358 -0.150004</pose>
          <velocity>0.000337 3.9e-05 -0.002196 0.002603 0.00783 -0.003425</velocity>
          <acceleration>-2.7672 4.91327 5.33349 0.844649 0.056202 -2.52087</acceleration>
          <wrench>-0.027672 0.049133 0.053335 0 -0 0</wrench>
        </link>
        <link name='gripper_palm_link'>
          <pose>4.23447 -0.61032 0.451787 -0.303878 0.22358 -0.150004</pose>
          <velocity>1.4e-05 0.000763 -0.002305 0.002827 0.008025 -0.003541</velocity>
          <acceleration>-2.46561 4.95625 5.07029 1.11891 0.293526 -2.66278</acceleration>
          <wrench>-0.246561 0.495625 0.507029 0 -0 0</wrench>
        </link>
        <link name='plate_link'>
          <pose>4.03643 -0.898071 0.129978 1.6e-05 2.6e-05 0.979743</pose>
          <velocity>0.000422 -0.000322 0.000542 0.003345 0.002544 -0.000454</velocity>
          <acceleration>0.133016 -0.184176 -0.131028 0.221332 -0.33272 0.171997</acceleration>
          <wrench>0.133016 -0.184176 -0.131028 0 -0 0</wrench>
        </link>
        <link name='wheel_link_bl'>
          <pose>3.86679 -0.867324 0.049999 1.5e-05 -0.110039 0.979918</pose>
          <velocity>0.000281 7.3e-05 0.000211 -0.001435 0.005677 -0.000127</velocity>
          <acceleration>0.022174 0.021587 -0.004445 -0.315651 0.550066 -0.034464</acceleration>
          <wrench>0.00887 0.008635 -0.001778 0 -0 0</wrench>
        </link>
        <link name='wheel_link_br'>
          <pose>4.12918 -1.04341 0.049995 1.5e-05 -0.085768 0.981504</pose>
          <velocity>0.000159 -0.000116 0.000349 0.002322 0.003217 -0.000295</velocity>
          <acceleration>0.041212 0.050255 0.014626 -0.826529 0.959561 -0.027094</acceleration>
          <wrench>0.016485 0.020102 0.00585 0 -0 0</wrench>
        </link>
        <link name='wheel_link_fl'>
          <pose>4.12088 -0.488682 0.049998 1.6e-05 0.068434 0.9863</pose>
          <velocity>0.000291 6.7e-05 0.000367 -0.001354 0.005821 -0.000149</velocity>
          <acceleration>0.017589 0.023413 -0.025014 -0.349503 0.439982 -0.036731</acceleration>
          <wrench>0.007036 0.009365 -0.010006 0 -0 0</wrench>
        </link>
        <link name='wheel_link_fr'>
          <pose>4.38328 -0.664768 0.049994 1.7e-05 0.10408 0.988499</pose>
          <velocity>0.000172 -0.00012 0.00051 0.002373 0.003416 -0.00028</velocity>
          <acceleration>0.04083 0.058861 -0.006038 -0.971793 0.950481 -0.041466</acceleration>
          <wrench>0.016332 0.023544 -0.002415 0 -0 0</wrench>
        </link>
      </model>
      <light name='sun'>
        <pose>0 0 10 0 -0 0</pose>
      </light>
    </state>
    <gui fullscreen='0'>
      <camera name='user_camera'>
        <pose>18.0954 -4.41772 3.4166 0 0.199004 2.96655</pose>
        <view_controller>orbit</view_controller>
        <projection_type>perspective</projection_type>
      </camera>
    </gui>
    <model name='basic_mobile_bot'>
      <static>0</static>
      <link name='chassis'>
        <pose>0 0 0.25 0 -0 0</pose>
        <collision name='collision'>
          <geometry>
            <box>
              <size>0.99 0.42 0.2</size>
            </box>
          </geometry>
          <max_contacts>10</max_contacts>
          <surface>
            <contact>
              <ode/>
            </contact>
            <bounce/>
            <friction>
              <torsional>
                <ode/>
              </torsional>
              <ode/>
            </friction>
          </surface>
        </collision>
        <visual name='visual'>
          <geometry>
            <box>
              <size>0.99 0.42 0.2</size>
            </box>
          </geometry>
        </visual>
        <self_collide>0</self_collide>
        <inertial>
          <pose>0 0 0 0 -0 0</pose>
          <inertia>
            <ixx>1</ixx>
            <ixy>0</ixy>
            <ixz>0</ixz>
            <iyy>1</iyy>
            <iyz>0</iyz>
            <izz>1</izz>
          </inertia>
          <mass>1</mass>
        </inertial>
        <enable_wind>0</enable_wind>
        <kinematic>0</kinematic>
        <description>The collision hitbox for the Husky.</description>
        <description>The visual body of the Husky.</description>
      </link>
      <link name='front_left_wheel'>
        <pose>0.272 0.27 0.165 -0 1.5707 1.5707</pose>
        <collision name='collision'>
          <geometry>
            <cylinder>
              <radius>0.165</radius>
              <length>0.125</length>
            </cylinder>
          </geometry>
          <max_contacts>10</max_contacts>
          <surface>
            <contact>
              <ode/>
            </contact>
            <bounce/>
            <friction>
              <torsional>
                <ode/>
              </torsional>
              <ode/>
            </friction>
          </surface>
        </collision>
        <visual name='visual'>
          <geometry>
            <cylinder>
              <radius>0.165</radius>
              <length>0.125</length>
            </cylinder>
          </geometry>
        </visual>
        <self_collide>0</self_collide>
        <inertial>
          <pose>0 0 0 0 -0 0</pose>
          <inertia>
            <ixx>1</ixx>
            <ixy>0</ixy>
            <ixz>0</ixz>
            <iyy>1</iyy>
            <iyz>0</iyz>
            <izz>1</izz>
          </inertia>
          <mass>1</mass>
        </inertial>
        <enable_wind>0</enable_wind>
        <kinematic>0</kinematic>
      </link>
      <link name='front_right_wheel'>
        <pose>0.272 -0.27 0.165 -0 1.5707 1.5707</pose>
        <collision name='collision'>
          <geometry>
            <cylinder>
              <radius>0.165</radius>
              <length>0.125</length>
            </cylinder>
          </geometry>
          <max_contacts>10</max_contacts>
          <surface>
            <contact>
              <ode/>
            </contact>
            <bounce/>
            <friction>
              <torsional>
                <ode/>
              </torsional>
              <ode/>
            </friction>
          </surface>
        </collision>
        <visual name='visual'>
          <geometry>
            <cylinder>
              <radius>0.165</radius>
              <length>0.125</length>
            </cylinder>
          </geometry>
        </visual>
        <self_collide>0</self_collide>
        <inertial>
          <pose>0 0 0 0 -0 0</pose>
          <inertia>
            <ixx>1</ixx>
            <ixy>0</ixy>
            <ixz>0</ixz>
            <iyy>1</iyy>
            <iyz>0</iyz>
            <izz>1</izz>
          </inertia>
          <mass>1</mass>
        </inertial>
        <enable_wind>0</enable_wind>
        <kinematic>0</kinematic>
      </link>
      <link name='rear_left_wheel'>
        <pose>-0.272 0.27 0.165 -0 1.5707 1.5707</pose>
        <collision name='collision'>
          <geometry>
            <cylinder>
              <radius>0.165</radius>
              <length>0.125</length>
            </cylinder>
          </geometry>
          <max_contacts>10</max_contacts>
          <surface>
            <contact>
              <ode/>
            </contact>
            <bounce/>
            <friction>
              <torsional>
                <ode/>
              </torsional>
              <ode/>
            </friction>
          </surface>
        </collision>
        <visual name='visual'>
          <geometry>
            <cylinder>
              <radius>0.165</radius>
              <length>0.125</length>
            </cylinder>
          </geometry>
        </visual>
        <self_collide>0</self_collide>
        <inertial>
          <pose>0 0 0 0 -0 0</pose>
          <inertia>
            <ixx>1</ixx>
            <ixy>0</ixy>
            <ixz>0</ixz>
            <iyy>1</iyy>
            <iyz>0</iyz>
            <izz>1</izz>
          </inertia>
          <mass>1</mass>
        </inertial>
        <enable_wind>0</enable_wind>
        <kinematic>0</kinematic>
      </link>
      <link name='rear_right_wheel'>
        <pose>-0.272 -0.27 0.165 -0 1.5707 1.5707</pose>
        <collision name='collision'>
          <geometry>
            <cylinder>
              <radius>0.165</radius>
              <length>0.125</length>
            </cylinder>
          </geometry>
          <max_contacts>10</max_contacts>
          <surface>
            <contact>
              <ode/>
            </contact>
            <bounce/>
            <friction>
              <torsional>
                <ode/>
              </torsional>
              <ode/>
            </friction>
          </surface>
        </collision>
        <visual name='visual'>
          <geometry>
            <cylinder>
              <radius>0.165</radius>
              <length>0.125</length>
            </cylinder>
          </geometry>
        </visual>
        <self_collide>0</self_collide>
        <inertial>
          <pose>0 0 0 0 -0 0</pose>
          <inertia>
            <ixx>1</ixx>
            <ixy>0</ixy>
            <ixz>0</ixz>
            <iyy>1</iyy>
            <iyz>0</iyz>
            <izz>1</izz>
          </inertia>
          <mass>1</mass>
        </inertial>
        <enable_wind>0</enable_wind>
        <kinematic>0</kinematic>
      </link>
      <joint name='front_left_wheel_hinge' type='revolute'>
        <pose>0 0 0.06 0 -0 0</pose>
        <child>front_left_wheel</child>
        <parent>chassis</parent>
        <axis>
          <xyz>0 0 1</xyz>
          <limit>
            <lower>-1e+16</lower>
            <upper>1e+16</upper>
          </limit>
          <dynamics>
            <spring_reference>0</spring_reference>
            <spring_stiffness>0</spring_stiffness>
          </dynamics>
        </axis>
      </joint>
      <joint name='front_right_wheel_hinge' type='revolute'>
        <pose>0 0 -0.06 0 -0 0</pose>
        <child>front_right_wheel</child>
        <parent>chassis</parent>
        <axis>
          <xyz>0 0 1</xyz>
          <limit>
            <lower>-1e+16</lower>
            <upper>1e+16</upper>
          </limit>
          <dynamics>
            <spring_reference>0</spring_reference>
            <spring_stiffness>0</spring_stiffness>
          </dynamics>
        </axis>
      </joint>
      <joint name='rear_left_wheel_hinge' type='fixed'>
        <pose>0 0 0.06 0 -0 0</pose>
        <child>rear_left_wheel</child>
        <parent>chassis</parent>
        <axis>
          <xyz>0 1 0</xyz>
          <limit>
            <lower>-1e+16</lower>
            <upper>1e+16</upper>
          </limit>
        </axis>
      </joint>
      <joint name='rear_right_wheel_hinge' type='fixed'>
        <pose>0 0 -0.06 0 -0 0</pose>
        <child>rear_right_wheel</child>
        <parent>chassis</parent>
        <axis>
          <xyz>0 1 0</xyz>
          <limit>
            <lower>-1e+16</lower>
            <upper>1e+16</upper>
          </limit>
        </axis>
      </joint>
      <link name='camera_depth_frame'>
        <pose>0.25 0 0.4 -1.5708 -0 -1.5708</pose>
        <self_collide>0</self_collide>
        <inertial>
          <pose>0 0 0 0 -0 0</pose>
          <inertia>
            <ixx>1</ixx>
            <ixy>0</ixy>
            <ixz>0</ixz>
            <iyy>1</iyy>
            <iyz>0</iyz>
            <izz>1</izz>
          </inertia>
          <mass>1</mass>
        </inertial>
        <enable_wind>0</enable_wind>
        <kinematic>0</kinematic>
      </link>
      <link name='cameralink'>
        <pose>0.25 0 0.4 0 -0 0</pose>
        <visual name='camera_visual'>
          <pose>-0.005 0 0 0 -0 0</pose>
          <geometry>
            <box>
              <size>0.015 0.08 0.022</size>
            </box>
          </geometry>
          <material>
            <ambient>0 0 0 1</ambient>
            <diffuse>0 0 0 1</diffuse>
            <specular>0 0 0 1</specular>
            <emissive>0 0 0 1</emissive>
          </material>
        </visual>
        <sensor name='depth_camera' type='camera'>
          <always_on>1</always_on>
          <visualize>0</visualize>
          <update_rate>5</update_rate>
          <camera name='camera'>
            <horizontal_fov>1.02974</horizontal_fov>
            <image>
              <width>640</width>
              <height>480</height>
              <format>R8G8B8</format>
            </image>
            <clip>
              <near>0.02</near>
              <far>10</far>
            </clip>
            <noise>
              <type>gaussian</type>
              <mean>0</mean>
              <stddev>0.007</stddev>
            </noise>
          </camera>
          <plugin name='depth_camera_controller' filename='libgazebo_ros_camera.so'>
            <camera_name>depth_camera</camera_name>
            <frame_name>camera_depth_frame</frame_name>
            <hack_baseline>0</hack_baseline>
            <min_depth>0.001</min_depth>
          </plugin>
        </sensor>
        <self_collide>0</self_collide>
        <inertial>
          <pose>0 0 0 0 -0 0</pose>
          <inertia>
            <ixx>1</ixx>
            <ixy>0</ixy>
            <ixz>0</ixz>
            <iyy>1</iyy>
            <iyz>0</iyz>
            <izz>1</izz>
          </inertia>
          <mass>1</mass>
        </inertial>
        <enable_wind>0</enable_wind>
        <kinematic>0</kinematic>
      </link>
      <joint name='camera_joint' type='fixed'>
        <child>cameralink</child>
        <parent>chassis</parent>
      </joint>
      <link name='imu_link'>
        <gravity>1</gravity>
        <sensor name='bmb_imu' type='imu'>
          <always_on>1</always_on>
          <update_rate>100</update_rate>
          <visualize>1</visualize>
          <imu>
            <angular_velocity>
              <x>
                <noise type='gaussian'>
                  <mean>0</mean>
                  <stddev>0.0002</stddev>
                </noise>
              </x>
              <y>
                <noise type='gaussian'>
                  <mean>0</mean>
                  <stddev>0.0002</stddev>
                </noise>
              </y>
              <z>
                <noise type='gaussian'>
                  <mean>0</mean>
                  <stddev>0.0002</stddev>
                </noise>
              </z>
            </angular_velocity>
            <linear_acceleration>
              <x>
                <noise type='gaussian'>
                  <mean>0</mean>
                  <stddev>0.017</stddev>
                </noise>
              </x>
              <y>
                <noise type='gaussian'>
                  <mean>0</mean>
                  <stddev>0.017</stddev>
                </noise>
              </y>
              <z>
                <noise type='gaussian'>
                  <mean>0</mean>
                  <stddev>0.017</stddev>
                </noise>
              </z>
            </linear_acceleration>
            <angular_velocity/>
            <linear_acceleration/>
            <orientation>
              <x>
                <noise type='gaussian'>
                  <mean>0.0</mean>
                  <stddev>2e-3</stddev>
                </noise>
              </x>
              <y>
                <noise type='gaussian'>
                  <mean>0.0</mean>
                  <stddev>2e-3</stddev>
                </noise>
              </y>
              <z>
                <noise type='gaussian'>
                  <mean>0.0</mean>
                  <stddev>2e-3</stddev>
                </noise>
              </z>
            </orientation>
          </imu>
          <plugin name='basic_mobile_bot_imu' filename='libgazebo_ros_imu_sensor.so'>
            <initial_orientation_as_reference>0</initial_orientation_as_reference>
            <frame_name>imu_link</frame_name>
            <ros>
              <namespace>/imu</namespace>
              <remapping>~/out:=data</remapping>
            </ros>
          </plugin>
        </sensor>
        <self_collide>0</self_collide>
        <inertial>
          <pose>0 0 0 0 -0 0</pose>
          <inertia>
            <ixx>1</ixx>
            <ixy>0</ixy>
            <ixz>0</ixz>
            <iyy>1</iyy>
            <iyz>0</iyz>
            <izz>1</izz>
          </inertia>
          <mass>1</mass>
        </inertial>
        <enable_wind>0</enable_wind>
        <kinematic>0</kinematic>
      </link>
      <link name='gps_link'>
        <sensor name='bmb_gps' type='gps'>
          <always_on>1</always_on>
          <update_rate>10</update_rate>
          <gps>
            <position_sensing>
              <horizontal>
                <noise type='gaussian'>
                  <mean>0</mean>
                  <stddev>0.01</stddev>
                </noise>
              </horizontal>
              <vertical>
                <noise type='gaussian'>
                  <mean>0</mean>
                  <stddev>1</stddev>
                </noise>
              </vertical>
            </position_sensing>
          </gps>
          <plugin name='basic_mobile_bot_gps' filename='libgazebo_ros_gps_sensor.so'>
            <ros>
              <remapping>~/out:=gps/fix</remapping>
            </ros>
          </plugin>
        </sensor>
        <self_collide>0</self_collide>
        <inertial>
          <pose>0 0 0 0 -0 0</pose>
          <inertia>
            <ixx>1</ixx>
            <ixy>0</ixy>
            <ixz>0</ixz>
            <iyy>1</iyy>
            <iyz>0</iyz>
            <izz>1</izz>
          </inertia>
          <mass>1</mass>
        </inertial>
        <enable_wind>0</enable_wind>
        <kinematic>0</kinematic>
      </link>
      <joint name='imu_joint' type='fixed'>
        <parent>base_link</parent>
        <child>imu_link</child>
        <pose>0 0 0 0 -0 0</pose>
      </joint>
      <joint name='gps_joint' type='fixed'>
        <parent>base_link</parent>
        <child>gps_link</child>
        <pose>0 0 0 0 -0 0</pose>
      </joint>
      <plugin name='basic_mobile_bot_diff_drive' filename='libgazebo_ros_diff_drive.so'>
        <update_rate>30</update_rate>
        <left_joint>front_left_wheel_hinge</left_joint>
        <right_joint>front_right_wheel_hinge</right_joint>
        <wheel_separation>0.52</wheel_separation>
        <wheel_diameter>0.28</wheel_diameter>
        <max_wheel_torque>20</max_wheel_torque>
        <max_wheel_acceleration>1.0</max_wheel_acceleration>
        <command_topic>cmd_vel</command_topic>
        <publish_odom>1</publish_odom>
        <publish_odom_tf>0</publish_odom_tf>
        <publish_wheel_tf>0</publish_wheel_tf>
        <odometry_topic>odom</odometry_topic>
        <odometry_frame>odom</odometry_frame>
        <robot_base_frame>base_footprint</robot_base_frame>
        <odometry_source>0</odometry_source>
        <ros>
          <remapping>odom:=wheel/odometry</remapping>
        </ros>
      </plugin>
      <plugin name='basic_mobile_bot_joint_state' filename='libgazebo_ros_joint_state_publisher.so'>
        <ros>
          <remapping>~/out:=joint_states</remapping>
        </ros>
        <update_rate>30</update_rate>
        <joint_name>front_left_wheel_hinge</joint_name>
        <joint_name>front_right_wheel_hinge</joint_name>
        <joint_name>rear_left_wheel_hinge</joint_name>
        <joint_name>rear_left_wheel_hinge</joint_name>
      </plugin>
      <pose>0 0 0 0 -0 0</pose>
      <description>The main body (chassis) of the Husky robot.</description>
      <description>Husky's front left wheel</description>
      <description>Husky's front right wheel</description>
      <description>Husky's rear left wheel</description>
      <description>Husky's rear right wheel</description>
      <description>Front left wheel hinge</description>
      <description>Front right wheel hinge</description>
      <description>Rear left wheel hinge</description>
      <description>Rear right wheel hinge</description>
      <description>Husky's camera sensor</description>
    </model>
    <model name='prius_hybrid'>
      <pose>10.6907 -4.30498 0.03 0 -0 0</pose>
      <link name='chassis'>
        <inertial>
          <mass>1326</mass>
          <pose>0 -0.266 0.48 0 -0 0</pose>
          <inertia>
            <ixx>2581.13</ixx>
            <ixy>0</ixy>
            <iyy>591.308</iyy>
            <ixz>0</ixz>
            <iyz>0</iyz>
            <izz>2681.95</izz>
          </inertia>
        </inertial>
        <visual name='chassis_visual'>
          <geometry>
            <mesh>
              <uri>model://prius_hybrid/meshes/Hybrid.obj</uri>
              <scale>0.01 0.01 0.01</scale>
              <submesh>
                <name>Hybrid</name>
                <center>0</center>
              </submesh>
            </mesh>
          </geometry>
        </visual>
        <visual name='interior_visual'>
          <geometry>
            <mesh>
              <uri>model://prius_hybrid/meshes/Hybrid.obj</uri>
              <scale>0.01 0.01 0.01</scale>
              <submesh>
                <name>Hybrid_Interior</name>
                <center>0</center>
              </submesh>
            </mesh>
          </geometry>
        </visual>
        <visual name='windows_visual'>
          <geometry>
            <mesh>
              <uri>model://prius_hybrid/meshes/Hybrid.obj</uri>
              <scale>0.01 0.01 0.01</scale>
              <submesh>
                <name>Hybrid_Windows</name>
                <center>0</center>
              </submesh>
            </mesh>
          </geometry>
        </visual>
        <collision name='chassis'>
          <pose>0 0.05 0.625 0 -0 0</pose>
          <geometry>
            <box>
              <size>1.7526 2.1 0.95</size>
            </box>
          </geometry>
          <max_contacts>10</max_contacts>
          <surface>
            <contact>
              <ode/>
            </contact>
            <bounce/>
            <friction>
              <torsional>
                <ode/>
              </torsional>
              <ode/>
            </friction>
          </surface>
        </collision>
        <collision name='front_bumper'>
          <pose>0 -2 0.458488 0 -0 0</pose>
          <geometry>
            <box>
              <size>1.33728 0.48 0.566691</size>
            </box>
          </geometry>
          <max_contacts>10</max_contacts>
          <surface>
            <contact>
              <ode/>
            </contact>
            <bounce/>
            <friction>
              <torsional>
                <ode/>
              </torsional>
              <ode/>
            </friction>
          </surface>
        </collision>
        <collision name='hood'>
          <pose>0 -1.90084 0.676305 0.341247 -0 0</pose>
          <geometry>
            <box>
              <size>1.59797 0.493107 0.265468</size>
            </box>
          </geometry>
          <max_contacts>10</max_contacts>
          <surface>
            <contact>
              <ode/>
            </contact>
            <bounce/>
            <friction>
              <torsional>
                <ode/>
              </torsional>
              <ode/>
            </friction>
          </surface>
        </collision>
        <collision name='windshield'>
          <pose>0 -0.875105 1.03227 0.335476 -0 0</pose>
          <geometry>
            <box>
              <size>1.16838 1.65425 0.272347</size>
            </box>
          </geometry>
          <max_contacts>10</max_contacts>
          <surface>
            <contact>
              <ode/>
            </contact>
            <bounce/>
            <friction>
              <torsional>
                <ode/>
              </torsional>
              <ode/>
            </friction>
          </surface>
        </collision>
        <collision name='top_front'>
          <pose>0 0.161236 1.38604 0.13503 -0 0</pose>
          <geometry>
            <box>
              <size>1.27915 0.625988 0.171868</size>
            </box>
          </geometry>
          <max_contacts>10</max_contacts>
          <surface>
            <contact>
              <ode/>
            </contact>
            <bounce/>
            <friction>
              <torsional>
                <ode/>
              </torsional>
              <ode/>
            </friction>
          </surface>
        </collision>
        <collision name='top_rear'>
          <pose>0 0.817696 1.36007 -0.068997 0 0</pose>
          <geometry>
            <box>
              <size>1.28513 0.771189 0.226557</size>
            </box>
          </geometry>
          <max_contacts>10</max_contacts>
          <surface>
            <contact>
              <ode/>
            </contact>
            <bounce/>
            <friction>
              <torsional>
                <ode/>
              </torsional>
              <ode/>
            </friction>
          </surface>
        </collision>
        <collision name='rear_window'>
          <pose>0 1.64053 1.17513 -0.262017 0 0</pose>
          <geometry>
            <box>
              <size>1.26785 1.11634 0.244286</size>
            </box>
          </geometry>
          <max_contacts>10</max_contacts>
          <surface>
            <contact>
              <ode/>
            </contact>
            <bounce/>
            <friction>
              <torsional>
                <ode/>
              </torsional>
              <ode/>
            </friction>
          </surface>
        </collision>
        <collision name='trunk'>
          <pose>0 1.63706 0.88818 0 -0 0</pose>
          <geometry>
            <box>
              <size>1.78806 1.13899 0.482746</size>
            </box>
          </geometry>
          <max_contacts>10</max_contacts>
          <surface>
            <contact>
              <ode/>
            </contact>
            <bounce/>
            <friction>
              <torsional>
                <ode/>
              </torsional>
              <ode/>
            </friction>
          </surface>
        </collision>
        <collision name='back_bumper'>
          <pose>0 2.05445 0.57787 0 -0 0</pose>
          <geometry>
            <box>
              <size>1.78165 0.512093 0.581427</size>
            </box>
          </geometry>
          <max_contacts>10</max_contacts>
          <surface>
            <contact>
              <ode/>
            </contact>
            <bounce/>
            <friction>
              <torsional>
                <ode/>
              </torsional>
              <ode/>
            </friction>
          </surface>
        </collision>
        <self_collide>0</self_collide>
        <enable_wind>0</enable_wind>
        <kinematic>0</kinematic>
      </link>
      <link name='steering_wheel'>
        <pose>0.357734 -0.627868 0.988243 -1.3021 0 0</pose>
        <inertial>
          <mass>1</mass>
          <inertia>
            <ixx>0.145833</ixx>
            <ixy>0</ixy>
            <ixz>0</ixz>
            <iyy>0.145833</iyy>
            <iyz>0</iyz>
            <izz>0.125</izz>
          </inertia>
          <pose>0 0 0 0 -0 0</pose>
        </inertial>
        <collision name='collision'>
          <geometry>
            <cylinder>
              <radius>0.178172</radius>
              <length>0.041845</length>
            </cylinder>
          </geometry>
          <surface>
            <contact>
              <ode>
                <min_depth>0.003</min_depth>
              </ode>
            </contact>
            <bounce/>
            <friction>
              <torsional>
                <ode/>
              </torsional>
              <ode/>
            </friction>
          </surface>
          <max_contacts>10</max_contacts>
        </collision>
        <visual name='visual'>
          <pose>0 0 0 1.3021 -0 0</pose>
          <geometry>
            <mesh>
              <uri>model://prius_hybrid/meshes/Hybrid.obj</uri>
              <scale>0.01 0.01 0.01</scale>
              <submesh>
                <name>Steering_Wheel</name>
                <center>1</center>
              </submesh>
            </mesh>
          </geometry>
        </visual>
        <self_collide>0</self_collide>
        <enable_wind>0</enable_wind>
        <kinematic>0</kinematic>
      </link>
      <link name='front_left_wheel'>
        <pose>0.76 -1.41 0.3 0 -0 0</pose>
        <inertial>
          <mass>11</mass>
          <inertia>
            <ixx>0.586312</ixx>
            <ixy>0</ixy>
            <iyy>0.335529</iyy>
            <ixz>0</ixz>
            <iyz>0</iyz>
            <izz>0.335529</izz>
          </inertia>
          <pose>0 0 0 0 -0 0</pose>
        </inertial>
        <visual name='visual'>
          <pose>0.04 0 0 0 -0 0</pose>
          <geometry>
            <mesh>
              <uri>model://prius_hybrid/meshes/Hybrid.obj</uri>
              <scale>0.01 0.01 0.01</scale>
              <submesh>
                <name>Wheel_Front_Left_</name>
                <center>1</center>
              </submesh>
            </mesh>
          </geometry>
        </visual>
        <collision name='collision'>
          <pose>0 0 0 3.14159 1.57079 3.14159</pose>
          <geometry>
            <sphere>
              <radius>0.31265</radius>
            </sphere>
          </geometry>
          <surface>
            <friction>
              <ode>
                <mu>0.9</mu>
                <mu2>0.9</mu2>
                <slip1>0</slip1>
                <slip2>0</slip2>
              </ode>
              <torsional>
                <ode/>
              </torsional>
            </friction>
            <contact>
              <ode>
                <min_depth>0.001</min_depth>
                <kp>1e+09</kp>
              </ode>
            </contact>
            <bounce/>
          </surface>
          <max_contacts>10</max_contacts>
        </collision>
        <self_collide>0</self_collide>
        <enable_wind>0</enable_wind>
        <kinematic>0</kinematic>
      </link>
      <link name='front_right_wheel'>
        <pose>-0.76 -1.41 0.3 0 -0 0</pose>
        <inertial>
          <mass>11</mass>
          <inertia>
            <ixx>0.586312</ixx>
            <ixy>0</ixy>
            <iyy>0.335529</iyy>
            <ixz>0</ixz>
            <iyz>0</iyz>
            <izz>0.335529</izz>
          </inertia>
          <pose>0 0 0 0 -0 0</pose>
        </inertial>
        <visual name='visual'>
          <pose>-0.04 0 0 0 -0 0</pose>
          <pose>0 0 0 0 -0 0</pose>
          <geometry>
            <mesh>
              <uri>model://prius_hybrid/meshes/Hybrid.obj</uri>
              <scale>0.01 0.01 0.01</scale>
              <submesh>
                <name>Wheel_Front_Right</name>
                <center>1</center>
              </submesh>
            </mesh>
          </geometry>
        </visual>
        <collision name='collision'>
          <pose>0 0 0 3.14159 1.57079 3.14159</pose>
          <geometry>
            <sphere>
              <radius>0.31265</radius>
            </sphere>
          </geometry>
          <surface>
            <friction>
              <ode>
                <mu>0.9</mu>
                <mu2>0.9</mu2>
                <slip1>0</slip1>
                <slip2>0</slip2>
              </ode>
              <torsional>
                <ode/>
              </torsional>
            </friction>
            <contact>
              <ode>
                <min_depth>0.001</min_depth>
                <kp>1e+09</kp>
              </ode>
            </contact>
            <bounce/>
          </surface>
          <max_contacts>10</max_contacts>
        </collision>
        <self_collide>0</self_collide>
        <enable_wind>0</enable_wind>
        <kinematic>0</kinematic>
      </link>
      <link name='rear_left_wheel'>
        <pose>0.786 1.45 0.3 0 -0 0</pose>
        <inertial>
          <mass>11</mass>
          <inertia>
            <ixx>0.586312</ixx>
            <ixy>0</ixy>
            <iyy>0.335529</iyy>
            <ixz>0</ixz>
            <iyz>0</iyz>
            <izz>0.335529</izz>
          </inertia>
          <pose>0 0 0 0 -0 0</pose>
        </inertial>
        <visual name='visual'>
          <pose>0.04 0 0 0 -0 0</pose>
          <geometry>
            <mesh>
              <uri>model://prius_hybrid/meshes/Hybrid.obj</uri>
              <scale>0.01 0.01 0.01</scale>
              <submesh>
                <name>Wheel_Front_Left_</name>
                <center>1</center>
              </submesh>
            </mesh>
          </geometry>
        </visual>
        <collision name='collision'>
          <pose>0 0 0 3.14159 1.57079 3.14159</pose>
          <geometry>
            <sphere>
              <radius>0.31265</radius>
            </sphere>
          </geometry>
          <surface>
            <friction>
              <ode>
                <mu>1.1</mu>
                <mu2>1.1</mu2>
                <slip1>0</slip1>
                <slip2>0</slip2>
              </ode>
              <torsional>
                <ode/>
              </torsional>
            </friction>
            <contact>
              <ode>
                <min_depth>0.001</min_depth>
                <kp>1e+09</kp>
              </ode>
            </contact>
            <bounce/>
          </surface>
          <max_contacts>10</max_contacts>
        </collision>
        <self_collide>0</self_collide>
        <enable_wind>0</enable_wind>
        <kinematic>0</kinematic>
      </link>
      <link name='rear_right_wheel'>
        <pose>-0.786 1.45 0.3 0 -0 0</pose>
        <inertial>
          <mass>11</mass>
          <inertia>
            <ixx>0.586312</ixx>
            <ixy>0</ixy>
            <iyy>0.335529</iyy>
            <ixz>0</ixz>
            <iyz>0</iyz>
            <izz>0.335529</izz>
          </inertia>
          <pose>0 0 0 0 -0 0</pose>
        </inertial>
        <visual name='visual'>
          <pose>-0.04 0 0 0 -0 0</pose>
          <geometry>
            <mesh>
              <uri>model://prius_hybrid/meshes/Hybrid.obj</uri>
              <scale>0.01 0.01 0.01</scale>
              <submesh>
                <name>Wheel_Front_Right</name>
                <center>1</center>
              </submesh>
            </mesh>
          </geometry>
        </visual>
        <collision name='collision'>
          <pose>0 0 0 3.14159 1.57079 3.14159</pose>
          <geometry>
            <sphere>
              <radius>0.31265</radius>
            </sphere>
          </geometry>
          <surface>
            <friction>
              <ode>
                <mu>1.1</mu>
                <mu2>1.1</mu2>
                <slip1>0</slip1>
                <slip2>0</slip2>
              </ode>
              <torsional>
                <ode/>
              </torsional>
            </friction>
            <contact>
              <ode>
                <min_depth>0.001</min_depth>
                <kp>1e+09</kp>
              </ode>
            </contact>
            <bounce/>
          </surface>
          <max_contacts>10</max_contacts>
        </collision>
        <self_collide>0</self_collide>
        <enable_wind>0</enable_wind>
        <kinematic>0</kinematic>
      </link>
      <joint name='front_left_combined_joint' type='universal'>
        <pose>0 0 0 -0.087266 0 0</pose>
        <child>front_left_wheel</child>
        <parent>chassis</parent>
        <axis>
          <xyz>0 0 1</xyz>
          <limit>
            <lower>-0.8727</lower>
            <upper>0.8727</upper>
          </limit>
          <dynamics>
            <spring_reference>0</spring_reference>
            <spring_stiffness>0</spring_stiffness>
          </dynamics>
        </axis>
        <axis2>
          <xyz>1 0 0</xyz>
          <dynamics>
            <friction>18.0474</friction>
            <spring_reference>0</spring_reference>
            <spring_stiffness>0</spring_stiffness>
          </dynamics>
          <limit>
            <upper>1e+16</upper>
            <lower>-1e+16</lower>
          </limit>
        </axis2>
      </joint>
      <joint name='front_right_combined_joint' type='universal'>
        <pose>0 0 0 -0.087266 0 0</pose>
        <child>front_right_wheel</child>
        <parent>chassis</parent>
        <axis>
          <xyz>0 0 1</xyz>
          <limit>
            <lower>-0.8727</lower>
            <upper>0.8727</upper>
          </limit>
          <dynamics>
            <spring_reference>0</spring_reference>
            <spring_stiffness>0</spring_stiffness>
          </dynamics>
        </axis>
        <axis2>
          <xyz>1 0 0</xyz>
          <dynamics>
            <friction>18.0474</friction>
            <spring_reference>0</spring_reference>
            <spring_stiffness>0</spring_stiffness>
          </dynamics>
          <limit>
            <upper>1e+16</upper>
            <lower>-1e+16</lower>
          </limit>
        </axis2>
      </joint>
      <link name='rear_axle'>
        <pose>0 1.45 0.3 0 -0 0</pose>
        <inertial>
          <mass>30</mass>
          <inertia>
            <ixx>0.084375</ixx>
            <ixy>0</ixy>
            <iyy>4.64581</iyy>
            <ixz>0</ixz>
            <iyz>0</iyz>
            <izz>4.64581</izz>
          </inertia>
          <pose>0 0 0 0 -0 0</pose>
        </inertial>
        <visual name='visual'>
          <pose>0 0 0 3.14159 1.57079 3.14159</pose>
          <geometry>
            <cylinder>
              <length>1.357</length>
              <radius>0.075</radius>
            </cylinder>
          </geometry>
          <material>
            <script>
              <name>Gazebo/Grey</name>
              <uri>file://media/materials/scripts/gazebo.material</uri>
            </script>
          </material>
        </visual>
        <self_collide>0</self_collide>
        <enable_wind>0</enable_wind>
        <kinematic>0</kinematic>
      </link>
      <joint name='rear_axle_joint' type='revolute'>
        <child>rear_axle</child>
        <parent>chassis</parent>
        <axis>
          <xyz>0 1 0</xyz>
          <limit>
            <lower>-0.0508906</lower>
            <upper>0.0508906</upper>
          </limit>
          <dynamics>
            <spring_stiffness>20000</spring_stiffness>
            <damping>2000</damping>
            <spring_reference>0</spring_reference>
          </dynamics>
        </axis>
      </joint>
      <joint name='rear_left_wheel_joint' type='revolute'>
        <child>rear_left_wheel</child>
        <parent>rear_axle</parent>
        <axis>
          <xyz>1 0 0</xyz>
          <dynamics>
            <friction>12.0316</friction>
            <spring_reference>0</spring_reference>
            <spring_stiffness>0</spring_stiffness>
          </dynamics>
          <limit>
            <lower>-1e+16</lower>
            <upper>1e+16</upper>
          </limit>
        </axis>
      </joint>
      <joint name='rear_right_wheel_joint' type='revolute'>
        <child>rear_right_wheel</child>
        <parent>rear_axle</parent>
        <axis>
          <xyz>1 0 0</xyz>
          <dynamics>
            <friction>12.0316</friction>
            <spring_reference>0</spring_reference>
            <spring_stiffness>0</spring_stiffness>
          </dynamics>
          <limit>
            <lower>-1e+16</lower>
            <upper>1e+16</upper>
          </limit>
        </axis>
      </joint>
      <joint name='steering_joint' type='revolute'>
        <pose>-0.002 0 0 0 -0 0</pose>
        <parent>chassis</parent>
        <child>steering_wheel</child>
        <axis>
          <xyz expressed_in='__model__'>0 0.964095 0.265556</xyz>
          <limit>
            <lower>-7.85</lower>
            <upper>7.85</upper>
          </limit>
          <dynamics>
            <damping>1</damping>
            <spring_reference>0</spring_reference>
            <spring_stiffness>0</spring_stiffness>
          </dynamics>
        </axis>
        <physics>
          <ode>
            <cfm_damping>1</cfm_damping>
            <limit>
              <cfm>0</cfm>
              <erp>0.2</erp>
            </limit>
          </ode>
        </physics>
      </joint>
    </model>
    <model name='suv'>
      <static>1</static>
      <link name='link'>
        <collision name='collision'>
          <pose>0 0 0 0 0 -1.5708</pose>
          <geometry>
            <mesh>
              <scale>0.06 0.06 0.06</scale>
              <uri>model://suv/meshes/suv.obj</uri>
            </mesh>
          </geometry>
          <max_contacts>10</max_contacts>
          <surface>
            <contact>
              <ode/>
            </contact>
            <bounce/>
            <friction>
              <torsional>
                <ode/>
              </torsional>
              <ode/>
            </friction>
          </surface>
        </collision>
        <visual name='visual'>
          <pose>0 0 0 0 0 -1.5708</pose>
          <geometry>
            <mesh>
              <scale>0.06 0.06 0.06</scale>
              <uri>model://suv/meshes/suv.obj</uri>
            </mesh>
          </geometry>
        </visual>
        <self_collide>0</self_collide>
        <enable_wind>0</enable_wind>
        <kinematic>0</kinematic>
      </link>
      <pose>10.4505 2.41672 0 0 -0 0</pose>
    </model>
    <model name='youbot'>
      <pose>7.26244 -1.60045 0.09 0 -0 0</pose>
      <link name='base_footprint'>
        <pose>0 0 0 0 -0 0</pose>
        <inertial>
          <pose>0 0 -0.05 0 -0 0</pose>
          <inertia>
            <ixx>1</ixx>
            <ixy>0</ixy>
            <ixz>0</ixz>
            <iyy>1</iyy>
            <iyz>0</iyz>
            <izz>1</izz>
          </inertia>
          <mass>0.1</mass>
        </inertial>
        <collision name='base_footprint_geom'>
          <pose>0 0 -0.05 0 -0 0</pose>
          <geometry>
            <box>
              <size>0.001 0.001 0.001</size>
            </box>
          </geometry>
          <surface>
            <friction>
              <ode>
                <mu>0</mu>
                <mu2>0</mu2>
                <fdir1>0 0 0</fdir1>
                <slip1>0</slip1>
                <slip2>0</slip2>
              </ode>
              <torsional>
                <ode/>
              </torsional>
            </friction>
            <bounce>
              <restitution_coefficient>0</restitution_coefficient>
              <threshold>0</threshold>
            </bounce>
            <contact>
              <ode>
                <soft_cfm>0</soft_cfm>
                <soft_erp>0.2</soft_erp>
                <kp>1e+13</kp>
                <kd>1e+11</kd>
                <max_vel>-1</max_vel>
                <min_depth>0</min_depth>
              </ode>
            </contact>
          </surface>
          <laser_retro>0</laser_retro>
          <max_contacts>10</max_contacts>
        </collision>
        <visual name='base_footprint_geom_visual'>
          <pose>0 0 0 0 -0 0</pose>
          <geometry>
            <box>
              <size>0.001 0.001 0.001</size>
            </box>
          </geometry>
        </visual>
        <gravity>1</gravity>
        <self_collide>0</self_collide>
        <kinematic>0</kinematic>
        <enable_wind>0</enable_wind>
      </link>
      <link name='base_link'>
        <pose>0 0 0 0 -0 0</pose>
        <inertial>
          <pose>0 0 0 0 -0 0</pose>
          <inertia>
            <ixx>5.65223</ixx>
            <ixy>-0.00972</ixy>
            <ixz>1.29399</ixz>
            <iyy>5.66947</iyy>
            <iyz>-0.00738</iyz>
            <izz>3.6832</izz>
          </inertia>
          <mass>22</mass>
        </inertial>
        <collision name='base_link_geom'>
          <pose>0 0 0 0 -0 0</pose>
          <geometry>
            <mesh>
              <uri>model://youbot/meshes/base/base_convex.stl</uri>
            </mesh>
          </geometry>
          <surface>
            <friction>
              <ode>
                <mu>0</mu>
                <mu2>0</mu2>
                <fdir1>0 0 0</fdir1>
                <slip1>0</slip1>
                <slip2>0</slip2>
              </ode>
              <torsional>
                <ode/>
              </torsional>
            </friction>
            <bounce>
              <restitution_coefficient>0</restitution_coefficient>
              <threshold>0</threshold>
            </bounce>
            <contact>
              <ode>
                <soft_cfm>0</soft_cfm>
                <soft_erp>0.2</soft_erp>
                <kp>1e+13</kp>
                <kd>1e+11</kd>
                <max_vel>-1</max_vel>
                <min_depth>0</min_depth>
              </ode>
            </contact>
          </surface>
          <laser_retro>0</laser_retro>
          <max_contacts>10</max_contacts>
        </collision>
        <visual name='base_link_geom_visual'>
          <pose>0 0 0 0 -0 0</pose>
          <geometry>
            <mesh>
              <uri>model://youbot/meshes/base/base.dae</uri>
            </mesh>
          </geometry>
        </visual>
        <gravity>1</gravity>
        <self_collide>0</self_collide>
        <kinematic>0</kinematic>
        <enable_wind>0</enable_wind>
      </link>
      <link name='arm_link_0'>
        <pose>0.143 0 0.046 0 -0 0</pose>
        <inertial>
          <pose>0 0 0 0 -0 0</pose>
          <inertia>
            <ixx>0.01</ixx>
            <ixy>0</ixy>
            <ixz>0</ixz>
            <iyy>0.01</iyy>
            <iyz>0</iyz>
            <izz>0.01</izz>
          </inertia>
          <mass>0.845</mass>
        </inertial>
        <collision name='arm_link_0_geom'>
          <pose>0 0 0 0 -0 0</pose>
          <geometry>
            <mesh>
              <uri>model://youbot/meshes/arm/arm0_convex.stl</uri>
            </mesh>
          </geometry>
          <surface>
            <friction>
              <ode>
                <mu>0</mu>
                <mu2>0</mu2>
                <fdir1>0 0 0</fdir1>
                <slip1>0</slip1>
                <slip2>0</slip2>
              </ode>
              <torsional>
                <ode/>
              </torsional>
            </friction>
            <bounce>
              <restitution_coefficient>0</restitution_coefficient>
              <threshold>0</threshold>
            </bounce>
            <contact>
              <ode>
                <soft_cfm>0</soft_cfm>
                <soft_erp>0.2</soft_erp>
                <kp>1e+13</kp>
                <kd>1e+11</kd>
                <max_vel>-1</max_vel>
                <min_depth>0</min_depth>
              </ode>
            </contact>
          </surface>
          <laser_retro>0</laser_retro>
          <max_contacts>10</max_contacts>
        </collision>
        <visual name='arm_link_0_geom_visual'>
          <pose>0 0 0 0 -0 0</pose>
          <geometry>
            <mesh>
              <uri>model://youbot/meshes/arm/arm0.dae</uri>
            </mesh>
          </geometry>
          <material>
            <script>
              <uri>model://youbot/materials/scripts/youbot.material</uri>
              <name>youbot/DarkGrey</name>
            </script>
          </material>
        </visual>
        <gravity>1</gravity>
        <self_collide>0</self_collide>
        <kinematic>0</kinematic>
        <enable_wind>0</enable_wind>
      </link>
      <link name='arm_link_1'>
        <pose>0.167 0 0.142 0 -0 2.96706</pose>
        <inertial>
          <pose>0.01489 0.00213 0.00213 0 -0 0</pose>
          <inertia>
            <ixx>0.003863</ixx>
            <ixy>-0.000979</ixy>
            <ixz>0</ixz>
            <iyy>0.006196</iyy>
            <iyz>0</iyz>
            <izz>0.006369</izz>
          </inertia>
          <mass>2.412</mass>
        </inertial>
        <collision name='arm_link_1_geom'>
          <pose>0 0 0 0 -0 0</pose>
          <geometry>
            <mesh>
              <uri>model://youbot/meshes/arm/arm1_convex.stl</uri>
            </mesh>
          </geometry>
          <surface>
            <friction>
              <ode>
                <mu>0</mu>
                <mu2>0</mu2>
                <fdir1>0 0 0</fdir1>
                <slip1>0</slip1>
                <slip2>0</slip2>
              </ode>
              <torsional>
                <ode/>
              </torsional>
            </friction>
            <bounce>
              <restitution_coefficient>0</restitution_coefficient>
              <threshold>0</threshold>
            </bounce>
            <contact>
              <ode>
                <soft_cfm>0</soft_cfm>
                <soft_erp>0.2</soft_erp>
                <kp>1e+13</kp>
                <kd>1e+11</kd>
                <max_vel>-1</max_vel>
                <min_depth>0</min_depth>
              </ode>
            </contact>
          </surface>
          <laser_retro>0</laser_retro>
          <max_contacts>10</max_contacts>
        </collision>
        <visual name='arm_link_1_geom_visual'>
          <pose>0 0 0 0 -0 0</pose>
          <geometry>
            <mesh>
              <uri>model://youbot/meshes/arm/arm1.dae</uri>
            </mesh>
          </geometry>
        </visual>
        <gravity>1</gravity>
        <self_collide>0</self_collide>
        <kinematic>0</kinematic>
        <enable_wind>0</enable_wind>
      </link>
      <link name='arm_link_2'>
        <pose>0.134501 0.00573 0.161 0 -1.13446 2.96706</pose>
        <inertial>
          <pose>0.10453 0.0017 -0.00297 0 -0 0</pose>
          <inertia>
            <ixx>0.000823</ixx>
            <ixy>0</ixy>
            <ixz>-0</ixz>
            <iyy>0.004447</iyy>
            <iyz>0</iyz>
            <izz>0.004439</izz>
          </inertia>
          <mass>1.155</mass>
        </inertial>
        <collision name='arm_link_2_geom'>
          <pose>0 -0.032 0.078 0 -0 0</pose>
          <geometry>
            <mesh>
              <uri>model://youbot/meshes/arm/arm2_convex.stl</uri>
            </mesh>
          </geometry>
          <surface>
            <friction>
              <ode>
                <mu>0</mu>
                <mu2>0</mu2>
                <fdir1>0 0 0</fdir1>
                <slip1>0</slip1>
                <slip2>0</slip2>
              </ode>
              <torsional>
                <ode/>
              </torsional>
            </friction>
            <bounce>
              <restitution_coefficient>0</restitution_coefficient>
              <threshold>0</threshold>
            </bounce>
            <contact>
              <ode>
                <soft_cfm>0</soft_cfm>
                <soft_erp>0.2</soft_erp>
                <kp>1e+13</kp>
                <kd>1e+11</kd>
                <max_vel>-1</max_vel>
                <min_depth>0</min_depth>
              </ode>
            </contact>
          </surface>
          <laser_retro>0</laser_retro>
          <max_contacts>10</max_contacts>
        </collision>
        <visual name='arm_link_2_geom_visual'>
          <pose>0 -0.032 0.078 0 -0 0</pose>
          <geometry>
            <mesh>
              <uri>model://youbot/meshes/arm/arm2.dae</uri>
            </mesh>
          </geometry>
        </visual>
        <gravity>1</gravity>
        <self_collide>0</self_collide>
        <kinematic>0</kinematic>
        <enable_wind>0</enable_wind>
      </link>
      <link name='arm_link_3'>
        <pose>0.272845 -0.018663 0.226506 -0 1.41372 2.96706</pose>
        <inertial>
          <pose>0.0001 0.0967 0.02107 0 -0 0</pose>
          <inertia>
            <ixx>0.002459</ixx>
            <ixy>0</ixy>
            <ixz>0</ixz>
            <iyy>0.002571</iyy>
            <iyz>-0</iyz>
            <izz>0.000535</izz>
          </inertia>
          <mass>0.934</mass>
        </inertial>
        <collision name='arm_link_3_geom'>
          <pose>0 0.028 0.079 0 -0 0</pose>
          <geometry>
            <mesh>
              <uri>model://youbot/meshes/arm/arm3_convex.stl</uri>
            </mesh>
          </geometry>
          <surface>
            <friction>
              <ode>
                <mu>0</mu>
                <mu2>0</mu2>
                <fdir1>0 0 0</fdir1>
                <slip1>0</slip1>
                <slip2>0</slip2>
              </ode>
              <torsional>
                <ode/>
              </torsional>
            </friction>
            <bounce>
              <restitution_coefficient>0</restitution_coefficient>
              <threshold>0</threshold>
            </bounce>
            <contact>
              <ode>
                <soft_cfm>0</soft_cfm>
                <soft_erp>0.2</soft_erp>
                <kp>1e+13</kp>
                <kd>1e+11</kd>
                <max_vel>-1</max_vel>
                <min_depth>0</min_depth>
              </ode>
            </contact>
          </surface>
          <laser_retro>0</laser_retro>
          <max_contacts>10</max_contacts>
        </collision>
        <visual name='arm_link_3_geom_visual'>
          <pose>0 0.028 0.079 0 -0 0</pose>
          <geometry>
            <mesh>
              <uri>model://youbot/meshes/arm/arm3.dae</uri>
            </mesh>
          </geometry>
        </visual>
        <gravity>1</gravity>
        <self_collide>0</self_collide>
        <kinematic>0</kinematic>
        <enable_wind>0</enable_wind>
      </link>
      <link name='arm_link_4'>
        <pose>0.141533 0.004491 0.247624 0 -0.375246 2.96706</pose>
        <inertial>
          <pose>0.00011 0.05103 -0.02319 0 -0 0</pose>
          <inertia>
            <ixx>0.000869</ixx>
            <ixy>0</ixy>
            <ixz>-0</ixz>
            <iyy>0.001173</iyy>
            <iyz>-0.000231</iyz>
            <izz>0.001091</izz>
          </inertia>
          <mass>0.877</mass>
        </inertial>
        <collision name='arm_link_4_geom'>
          <pose>0 -0.01 0.029 0 -0 0</pose>
          <geometry>
            <mesh>
              <uri>model://youbot/meshes/arm/arm4_convex.stl</uri>
            </mesh>
          </geometry>
          <surface>
            <friction>
              <ode>
                <mu>0</mu>
                <mu2>0</mu2>
                <fdir1>0 0 0</fdir1>
                <slip1>0</slip1>
                <slip2>0</slip2>
              </ode>
              <torsional>
                <ode/>
              </torsional>
            </friction>
            <bounce>
              <restitution_coefficient>0</restitution_coefficient>
              <threshold>0</threshold>
            </bounce>
            <contact>
              <ode>
                <soft_cfm>0</soft_cfm>
                <soft_erp>0.2</soft_erp>
                <kp>1e+13</kp>
                <kd>1e+11</kd>
                <max_vel>-1</max_vel>
                <min_depth>0</min_depth>
              </ode>
            </contact>
          </surface>
          <laser_retro>0</laser_retro>
          <max_contacts>10</max_contacts>
        </collision>
        <visual name='arm_link_4_geom_visual'>
          <pose>0 -0.01 0.029 0 -0 0</pose>
          <geometry>
            <mesh>
              <uri>model://youbot/meshes/arm/arm4.dae</uri>
            </mesh>
          </geometry>
        </visual>
        <gravity>1</gravity>
        <self_collide>0</self_collide>
        <kinematic>0</kinematic>
        <enable_wind>0</enable_wind>
      </link>
      <link name='arm_link_5'>
        <pose>0.190287 -0.004106 0.367846 -0.085052 0.365926 -0.408445</pose>
        <inertial>
          <pose>0 0.00115 -0.01683 0 -0 0</pose>
          <inertia>
            <ixx>0.00028</ixx>
            <ixy>0</ixy>
            <ixz>0</ixz>
            <iyy>0.000339</iyy>
            <iyz>0</iyz>
            <izz>0.000119</izz>
          </inertia>
          <mass>0.251</mass>
        </inertial>
        <collision name='arm_link_5_geom'>
          <pose>0.003 0 -0.034 0 -0 0</pose>
          <geometry>
            <mesh>
              <uri>model://youbot/meshes/arm/arm5_convex.stl</uri>
            </mesh>
          </geometry>
          <surface>
            <bounce>
              <restitution_coefficient>0</restitution_coefficient>
              <threshold>0</threshold>
            </bounce>
            <contact>
              <ode>
                <soft_cfm>0</soft_cfm>
                <soft_erp>0.2</soft_erp>
                <kp>1e+13</kp>
                <kd>1e+11</kd>
                <max_vel>-1</max_vel>
                <min_depth>0</min_depth>
              </ode>
            </contact>
            <friction>
              <torsional>
                <ode/>
              </torsional>
              <ode/>
            </friction>
          </surface>
          <laser_retro>0</laser_retro>
          <max_contacts>10</max_contacts>
        </collision>
        <visual name='arm_link_5_geom_visual'>
          <pose>0.003 0 -0.034 0 -0 0</pose>
          <geometry>
            <mesh>
              <uri>model://youbot/meshes/arm/arm5.dae</uri>
            </mesh>
          </geometry>
        </visual>
        <gravity>1</gravity>
        <self_collide>0</self_collide>
        <kinematic>0</kinematic>
        <enable_wind>0</enable_wind>
      </link>
      <link name='gripper_palm_link'>
        <pose>0.190287 -0.004106 0.367846 -0.085052 0.365926 -0.408445</pose>
        <inertial>
          <pose>0 0 0 0 -0 0</pose>
          <inertia>
            <ixx>0.01</ixx>
            <ixy>0</ixy>
            <ixz>0</ixz>
            <iyy>0.01</iyy>
            <iyz>0</iyz>
            <izz>0.01</izz>
          </inertia>
          <mass>0.1</mass>
        </inertial>
        <collision name='gripper_palm_link_geom'>
          <pose>0 0 0 0 -0 0</pose>
          <geometry>
            <mesh>
              <uri>model://youbot/meshes/gripper/palm_convex.stl</uri>
            </mesh>
          </geometry>
          <surface>
            <friction>
              <ode>
                <mu>0</mu>
                <mu2>0</mu2>
                <fdir1>0 0 0</fdir1>
                <slip1>0</slip1>
                <slip2>0</slip2>
              </ode>
              <torsional>
                <ode/>
              </torsional>
            </friction>
            <bounce>
              <restitution_coefficient>0</restitution_coefficient>
              <threshold>0</threshold>
            </bounce>
            <contact>
              <ode>
                <soft_cfm>0</soft_cfm>
                <soft_erp>0.2</soft_erp>
                <kp>1e+13</kp>
                <kd>1e+11</kd>
                <max_vel>-1</max_vel>
                <min_depth>0</min_depth>
              </ode>
            </contact>
          </surface>
          <laser_retro>0</laser_retro>
          <max_contacts>10</max_contacts>
        </collision>
        <visual name='gripper_palm_link_geom_visual'>
          <pose>0 0 0 0 -0 0</pose>
          <geometry>
            <mesh>
              <uri>model://youbot/meshes/gripper/palm.stl</uri>
            </mesh>
          </geometry>
          <material>
            <script>
              <uri>file://media/materials/scripts/gazebo.material</uri>
              <name>Gazebo/Black</name>
            </script>
          </material>
        </visual>
        <gravity>1</gravity>
        <self_collide>1</self_collide>
        <kinematic>0</kinematic>
        <enable_wind>0</enable_wind>
      </link>
      <link name='gripper_finger_link_l'>
        <pose>0.21326 -0.001105 0.408579 0.085052 -0.365926 2.73315</pose>
        <inertial>
          <pose>0 -0.001 0 0 -0 0</pose>
          <inertia>
            <ixx>0.01</ixx>
            <ixy>0</ixy>
            <ixz>0</ixz>
            <iyy>0.01</iyy>
            <iyz>0</iyz>
            <izz>0.01</izz>
          </inertia>
          <mass>0.01</mass>
        </inertial>
        <collision name='gripper_finger_link_l_geom'>
          <pose>0 0 0 0 -0 0</pose>
          <geometry>
            <mesh>
              <uri>model://youbot/meshes/gripper/finger_convex.stl</uri>
            </mesh>
          </geometry>
          <surface>
            <bounce>
              <restitution_coefficient>0</restitution_coefficient>
              <threshold>0</threshold>
            </bounce>
            <contact>
              <ode>
                <soft_cfm>0</soft_cfm>
                <soft_erp>0.2</soft_erp>
                <kp>1e+13</kp>
                <kd>1e+11</kd>
                <max_vel>-1</max_vel>
                <min_depth>0</min_depth>
              </ode>
            </contact>
            <friction>
              <torsional>
                <ode/>
              </torsional>
              <ode/>
            </friction>
          </surface>
          <laser_retro>0</laser_retro>
          <max_contacts>10</max_contacts>
        </collision>
        <visual name='gripper_finger_link_l_geom_visual'>
          <pose>0 0 0 0 -0 0</pose>
          <geometry>
            <mesh>
              <uri>model://youbot/meshes/gripper/finger.stl</uri>
            </mesh>
          </geometry>
        </visual>
        <gravity>1</gravity>
        <self_collide>0</self_collide>
        <kinematic>0</kinematic>
        <enable_wind>0</enable_wind>
      </link>
      <link name='gripper_finger_link_r'>
        <pose>0.207375 -0.015929 0.409848 -0.085052 0.365926 -0.408445</pose>
        <inertial>
          <pose>0 -0.001 0 0 -0 0</pose>
          <inertia>
            <ixx>0.01</ixx>
            <ixy>0</ixy>
            <ixz>0</ixz>
            <iyy>0.01</iyy>
            <iyz>0</iyz>
            <izz>0.01</izz>
          </inertia>
          <mass>0.01</mass>
        </inertial>
        <collision name='gripper_finger_link_r_geom'>
          <pose>0 0 0 0 -0 0</pose>
          <geometry>
            <mesh>
              <uri>model://youbot/meshes/gripper/finger_convex.stl</uri>
            </mesh>
          </geometry>
          <surface>
            <bounce>
              <restitution_coefficient>0</restitution_coefficient>
              <threshold>0</threshold>
            </bounce>
            <contact>
              <ode>
                <soft_cfm>0</soft_cfm>
                <soft_erp>0.2</soft_erp>
                <kp>1e+13</kp>
                <kd>1e+11</kd>
                <max_vel>-1</max_vel>
                <min_depth>0</min_depth>
              </ode>
            </contact>
            <friction>
              <torsional>
                <ode/>
              </torsional>
              <ode/>
            </friction>
          </surface>
          <laser_retro>0</laser_retro>
          <max_contacts>10</max_contacts>
        </collision>
        <visual name='gripper_finger_link_r_geom_visual'>
          <pose>0 0 0 0 -0 0</pose>
          <geometry>
            <mesh>
              <uri>model://youbot/meshes/gripper/finger.stl</uri>
            </mesh>
          </geometry>
        </visual>
        <gravity>1</gravity>
        <self_collide>0</self_collide>
        <kinematic>0</kinematic>
        <enable_wind>0</enable_wind>
      </link>
      <link name='base_laser_front_link'>
        <pose>0.3 0 -0.03 0 -0 0</pose>
        <inertial>
          <pose>0 0 0 0 -0 0</pose>
          <inertia>
            <ixx>0.1</ixx>
            <ixy>0</ixy>
            <ixz>0</ixz>
            <iyy>0.1</iyy>
            <iyz>0</iyz>
            <izz>0.1</izz>
          </inertia>
          <mass>0.16</mass>
        </inertial>
        <collision name='base_laser_front_link_geom'>
          <pose>0 0 0 0 -0 0</pose>
          <geometry>
            <mesh>
              <uri>model://hokuyo/meshes/hokuyo_convex.stl</uri>
            </mesh>
          </geometry>
          <surface>
            <bounce>
              <restitution_coefficient>0</restitution_coefficient>
              <threshold>0</threshold>
            </bounce>
            <contact>
              <ode>
                <soft_cfm>0</soft_cfm>
                <soft_erp>0.2</soft_erp>
                <kp>1e+13</kp>
                <kd>1e+11</kd>
                <max_vel>-1</max_vel>
                <min_depth>0</min_depth>
              </ode>
            </contact>
            <friction>
              <torsional>
                <ode/>
              </torsional>
              <ode/>
            </friction>
          </surface>
          <laser_retro>0</laser_retro>
          <max_contacts>10</max_contacts>
        </collision>
        <visual name='base_laser_front_link_geom_visual'>
          <pose>0 0 0 0 -0 0</pose>
          <geometry>
            <mesh>
              <uri>model://hokuyo/meshes/hokuyo.dae</uri>
            </mesh>
          </geometry>
        </visual>
        <sensor name='base_laser_front' type='ray'>
          <pose>0 0 0 0 -0 0</pose>
          <ray>
            <scan>
              <horizontal>
                <samples>640</samples>
                <resolution>1</resolution>
                <min_angle>-1.57</min_angle>
                <max_angle>1.57</max_angle>
              </horizontal>
              <vertical>
                <samples>1</samples>
                <min_angle>0</min_angle>
                <max_angle>0</max_angle>
              </vertical>
            </scan>
            <range>
              <min>0.05</min>
              <max>5.6</max>
              <resolution>0.36</resolution>
            </range>
          </ray>
          <always_on>0</always_on>
          <update_rate>10</update_rate>
          <visualize>0</visualize>
        </sensor>
        <gravity>1</gravity>
        <self_collide>0</self_collide>
        <kinematic>0</kinematic>
        <enable_wind>0</enable_wind>
      </link>
      <link name='caster_link_bl'>
        <pose>-0.228 0.158 -0.034 0 -0 0</pose>
        <inertial>
          <pose>0 0 0 0 -0 0</pose>
          <inertia>
            <ixx>0.012412</ixx>
            <ixy>-0.000712</ixy>
            <ixz>0.000503</ixz>
            <iyy>0.015218</iyy>
            <iyz>-4e-06</iyz>
            <izz>0.011764</izz>
          </inertia>
          <mass>0.1</mass>
        </inertial>
        <gravity>1</gravity>
        <self_collide>0</self_collide>
        <kinematic>0</kinematic>
        <enable_wind>0</enable_wind>
      </link>
      <link name='wheel_link_bl'>
        <pose>-0.228 0.158 -0.034 0 -0 0</pose>
        <inertial>
          <pose>0 0 0 0 -0 0</pose>
          <inertia>
            <ixx>0.012412</ixx>
            <ixy>-0.000712</ixy>
            <ixz>0.000503</ixz>
            <iyy>0.015218</iyy>
            <iyz>-4e-06</iyz>
            <izz>0.011764</izz>
          </inertia>
          <mass>0.4</mass>
        </inertial>
        <collision name='wheel_link_bl_geom'>
          <pose>0 0 0 1.5708 -0 0</pose>
          <geometry>
            <cylinder>
              <radius>0.05</radius>
              <length>0.005</length>
            </cylinder>
          </geometry>
          <surface>
            <bounce>
              <restitution_coefficient>0</restitution_coefficient>
              <threshold>0</threshold>
            </bounce>
            <contact>
              <ode>
                <soft_cfm>0</soft_cfm>
                <soft_erp>0.2</soft_erp>
                <kp>1e+13</kp>
                <kd>1e+11</kd>
                <max_vel>-1</max_vel>
                <min_depth>0</min_depth>
              </ode>
            </contact>
            <friction>
              <torsional>
                <ode/>
              </torsional>
              <ode/>
            </friction>
          </surface>
          <laser_retro>0</laser_retro>
          <max_contacts>10</max_contacts>
        </collision>
        <visual name='wheel_link_bl_geom_visual'>
          <pose>0 0 0 0 -0 0</pose>
          <geometry>
            <mesh>
              <uri>model://youbot/meshes/base/back-left_wheel.dae</uri>
            </mesh>
          </geometry>
          <material>
            <script>
              <uri>model://youbot/materials/scripts/youbot.material</uri>
              <name>youbot/Orange</name>
            </script>
          </material>
        </visual>
        <gravity>1</gravity>
        <self_collide>0</self_collide>
        <kinematic>0</kinematic>
        <enable_wind>0</enable_wind>
      </link>
      <link name='caster_link_br'>
        <pose>-0.228 -0.158 -0.034 0 -0 0</pose>
        <inertial>
          <pose>0 0 0 0 -0 0</pose>
          <inertia>
            <ixx>0.012412</ixx>
            <ixy>-0.000712</ixy>
            <ixz>0.000503</ixz>
            <iyy>0.015218</iyy>
            <iyz>-4e-06</iyz>
            <izz>0.011764</izz>
          </inertia>
          <mass>0.1</mass>
        </inertial>
        <gravity>1</gravity>
        <self_collide>0</self_collide>
        <kinematic>0</kinematic>
        <enable_wind>0</enable_wind>
      </link>
      <link name='wheel_link_br'>
        <pose>-0.228 -0.158 -0.034 0 -0 0</pose>
        <inertial>
          <pose>0 0 0 0 -0 0</pose>
          <inertia>
            <ixx>0.012412</ixx>
            <ixy>-0.000712</ixy>
            <ixz>0.000503</ixz>
            <iyy>0.015218</iyy>
            <iyz>-4e-06</iyz>
            <izz>0.011764</izz>
          </inertia>
          <mass>0.4</mass>
        </inertial>
        <collision name='wheel_link_br_geom'>
          <pose>0 0 0 1.5708 -0 0</pose>
          <geometry>
            <cylinder>
              <radius>0.05</radius>
              <length>0.005</length>
            </cylinder>
          </geometry>
          <surface>
            <bounce>
              <restitution_coefficient>0</restitution_coefficient>
              <threshold>0</threshold>
            </bounce>
            <contact>
              <ode>
                <soft_cfm>0</soft_cfm>
                <soft_erp>0.2</soft_erp>
                <kp>1e+13</kp>
                <kd>1e+11</kd>
                <max_vel>-1</max_vel>
                <min_depth>0</min_depth>
              </ode>
            </contact>
            <friction>
              <torsional>
                <ode/>
              </torsional>
              <ode/>
            </friction>
          </surface>
          <laser_retro>0</laser_retro>
          <max_contacts>10</max_contacts>
        </collision>
        <visual name='wheel_link_br_geom_visual'>
          <pose>0 0 0 0 -0 0</pose>
          <geometry>
            <mesh>
              <uri>model://youbot/meshes/base/back-right_wheel.dae</uri>
            </mesh>
          </geometry>
          <material>
            <script>
              <uri>model://youbot/materials/scripts/youbot.material</uri>
              <name>youbot/Orange</name>
            </script>
          </material>
        </visual>
        <gravity>1</gravity>
        <self_collide>0</self_collide>
        <kinematic>0</kinematic>
        <enable_wind>0</enable_wind>
      </link>
      <link name='caster_link_fl'>
        <pose>0.228 0.158 -0.034 0 -0 0</pose>
        <inertial>
          <pose>0 0 0 0 -0 0</pose>
          <inertia>
            <ixx>0.012412</ixx>
            <ixy>-0.000712</ixy>
            <ixz>0.000503</ixz>
            <iyy>0.015218</iyy>
            <iyz>-4e-06</iyz>
            <izz>0.011764</izz>
          </inertia>
          <mass>0.1</mass>
        </inertial>
        <gravity>1</gravity>
        <self_collide>0</self_collide>
        <kinematic>0</kinematic>
        <enable_wind>0</enable_wind>
      </link>
      <link name='wheel_link_fl'>
        <pose>0.228 0.158 -0.034 0 -0 0</pose>
        <inertial>
          <pose>0 0 0 0 -0 0</pose>
          <inertia>
            <ixx>0.012412</ixx>
            <ixy>-0.000712</ixy>
            <ixz>0.000503</ixz>
            <iyy>0.015218</iyy>
            <iyz>-4e-06</iyz>
            <izz>0.011764</izz>
          </inertia>
          <mass>0.4</mass>
        </inertial>
        <collision name='wheel_link_fl_geom'>
          <pose>0 0 0 1.5708 -0 0</pose>
          <geometry>
            <cylinder>
              <radius>0.05</radius>
              <length>0.005</length>
            </cylinder>
          </geometry>
          <surface>
            <bounce>
              <restitution_coefficient>0</restitution_coefficient>
              <threshold>0</threshold>
            </bounce>
            <contact>
              <ode>
                <soft_cfm>0</soft_cfm>
                <soft_erp>0.2</soft_erp>
                <kp>1e+13</kp>
                <kd>1e+11</kd>
                <max_vel>-1</max_vel>
                <min_depth>0</min_depth>
              </ode>
            </contact>
            <friction>
              <torsional>
                <ode/>
              </torsional>
              <ode/>
            </friction>
          </surface>
          <laser_retro>0</laser_retro>
          <max_contacts>10</max_contacts>
        </collision>
        <visual name='wheel_link_fl_geom_visual'>
          <pose>0 0 0 0 -0 0</pose>
          <geometry>
            <mesh>
              <uri>model://youbot/meshes/base/front-left_wheel.dae</uri>
            </mesh>
          </geometry>
          <material>
            <script>
              <uri>model://youbot/materials/scripts/youbot.material</uri>
              <name>youbot/Orange</name>
            </script>
          </material>
        </visual>
        <gravity>1</gravity>
        <self_collide>0</self_collide>
        <kinematic>0</kinematic>
        <enable_wind>0</enable_wind>
      </link>
      <link name='caster_link_fr'>
        <pose>0.228 -0.158 -0.034 0 -0 0</pose>
        <inertial>
          <pose>0 0 0 0 -0 0</pose>
          <inertia>
            <ixx>0.012412</ixx>
            <ixy>-0.000712</ixy>
            <ixz>0.000503</ixz>
            <iyy>0.015218</iyy>
            <iyz>-4e-06</iyz>
            <izz>0.011764</izz>
          </inertia>
          <mass>0.1</mass>
        </inertial>
        <gravity>1</gravity>
        <self_collide>0</self_collide>
        <kinematic>0</kinematic>
        <enable_wind>0</enable_wind>
      </link>
      <link name='wheel_link_fr'>
        <pose>0.228 -0.158 -0.034 0 -0 0</pose>
        <inertial>
          <pose>0 0 0 0 -0 0</pose>
          <inertia>
            <ixx>0.012412</ixx>
            <ixy>-0.000712</ixy>
            <ixz>0.000503</ixz>
            <iyy>0.015218</iyy>
            <iyz>-4e-06</iyz>
            <izz>0.011764</izz>
          </inertia>
          <mass>0.4</mass>
        </inertial>
        <collision name='wheel_link_fr_geom'>
          <pose>0 0 0 1.5708 -0 0</pose>
          <geometry>
            <cylinder>
              <radius>0.05</radius>
              <length>0.005</length>
            </cylinder>
          </geometry>
          <surface>
            <bounce>
              <restitution_coefficient>0</restitution_coefficient>
              <threshold>0</threshold>
            </bounce>
            <contact>
              <ode>
                <soft_cfm>0</soft_cfm>
                <soft_erp>0.2</soft_erp>
                <kp>1e+13</kp>
                <kd>1e+11</kd>
                <max_vel>-1</max_vel>
                <min_depth>0</min_depth>
              </ode>
            </contact>
            <friction>
              <torsional>
                <ode/>
              </torsional>
              <ode/>
            </friction>
          </surface>
          <laser_retro>0</laser_retro>
          <max_contacts>10</max_contacts>
        </collision>
        <visual name='wheel_link_fr_geom_visual'>
          <pose>0 0 0 0 -0 0</pose>
          <geometry>
            <mesh>
              <uri>model://youbot/meshes/base/front-right_wheel.dae</uri>
            </mesh>
          </geometry>
          <material>
            <script>
              <uri>model://youbot/materials/scripts/youbot.material</uri>
              <name>youbot/Orange</name>
            </script>
          </material>
        </visual>
        <gravity>1</gravity>
        <self_collide>0</self_collide>
        <kinematic>0</kinematic>
        <enable_wind>0</enable_wind>
      </link>
      <link name='plate_link'>
        <pose>-0.159 0 0.046 0 -0 0</pose>
        <inertial>
          <pose>0 0 0 0 -0 0</pose>
          <inertia>
            <ixx>0.01</ixx>
            <ixy>0</ixy>
            <ixz>0</ixz>
            <iyy>0.01</iyy>
            <iyz>0</iyz>
            <izz>0.01</izz>
          </inertia>
          <mass>1</mass>
        </inertial>
        <collision name='plate_link_geom'>
          <pose>0 0 0 0 -0 0</pose>
          <geometry>
            <mesh>
              <uri>model://youbot/meshes/plate/plate_convex.stl</uri>
            </mesh>
          </geometry>
          <surface>
            <bounce>
              <restitution_coefficient>0</restitution_coefficient>
              <threshold>0</threshold>
            </bounce>
            <contact>
              <ode>
                <soft_cfm>0</soft_cfm>
                <soft_erp>0.2</soft_erp>
                <kp>1e+13</kp>
                <kd>1e+11</kd>
                <max_vel>-1</max_vel>
                <min_depth>0</min_depth>
              </ode>
            </contact>
            <friction>
              <torsional>
                <ode/>
              </torsional>
              <ode/>
            </friction>
          </surface>
          <laser_retro>0</laser_retro>
          <max_contacts>10</max_contacts>
        </collision>
        <visual name='plate_link_geom_visual'>
          <pose>0 0 0 0 -0 0</pose>
          <geometry>
            <mesh>
              <uri>model://youbot/meshes/plate/plate.dae</uri>
            </mesh>
          </geometry>
        </visual>
        <gravity>1</gravity>
        <self_collide>0</self_collide>
        <kinematic>0</kinematic>
        <enable_wind>0</enable_wind>
      </link>
      <joint name='base_footprint_joint' type='revolute'>
        <pose>0 0 0 0 -0 0</pose>
        <parent>base_footprint</parent>
        <child>base_link</child>
        <axis>
          <dynamics>
            <damping>0</damping>
            <friction>0</friction>
            <spring_reference>0</spring_reference>
            <spring_stiffness>0</spring_stiffness>
          </dynamics>
          <limit>
            <lower>0</lower>
            <upper>0</upper>
            <effort>0</effort>
            <velocity>0</velocity>
          </limit>
          <xyz expressed_in='__model__'>0 0 1</xyz>
        </axis>
      </joint>
      <joint name='arm_joint_0' type='revolute'>
        <pose>0 0 0 0 -0 0</pose>
        <parent>base_link</parent>
        <child>arm_link_0</child>
        <axis>
          <dynamics>
            <damping>0</damping>
            <friction>0</friction>
            <spring_reference>0</spring_reference>
            <spring_stiffness>0</spring_stiffness>
          </dynamics>
          <limit>
            <lower>0</lower>
            <upper>0</upper>
            <effort>0</effort>
            <velocity>0</velocity>
          </limit>
          <xyz expressed_in='__model__'>0 0 1</xyz>
        </axis>
      </joint>
      <joint name='arm_joint_1' type='revolute'>
        <pose>0 0 0 0 -0 0</pose>
        <parent>arm_link_0</parent>
        <child>arm_link_1</child>
        <axis>
          <dynamics>
            <damping>1</damping>
            <friction>0</friction>
            <spring_reference>0</spring_reference>
            <spring_stiffness>0</spring_stiffness>
          </dynamics>
          <limit>
            <lower>0</lower>
            <upper>5.89921</upper>
            <effort>9.5</effort>
          </limit>
          <xyz expressed_in='__model__'>0 0 -1</xyz>
        </axis>
      </joint>
      <joint name='arm_joint_2' type='revolute'>
        <pose>0 0 0 0 -0 0</pose>
        <parent>arm_link_1</parent>
        <child>arm_link_2</child>
        <axis>
          <dynamics>
            <damping>1</damping>
            <friction>0</friction>
            <spring_reference>0</spring_reference>
            <spring_stiffness>0</spring_stiffness>
          </dynamics>
          <limit>
            <lower>0</lower>
            <upper>2.70526</upper>
            <effort>9.5</effort>
            <velocity>-1</velocity>
          </limit>
          <xyz expressed_in='__model__'>-0.173648 -0.984808 0</xyz>
        </axis>
      </joint>
      <joint name='arm_joint_3' type='revolute'>
        <pose>0 0 0 0 -0 0</pose>
        <parent>arm_link_2</parent>
        <child>arm_link_3</child>
        <axis>
          <dynamics>
            <damping>1</damping>
            <friction>0</friction>
            <spring_reference>0</spring_reference>
            <spring_stiffness>0</spring_stiffness>
          </dynamics>
          <limit>
            <lower>-5.18363</lower>
            <upper>0</upper>
            <effort>6</effort>
            <velocity>-1</velocity>
          </limit>
          <xyz expressed_in='__model__'>-0.173648 -0.984808 0</xyz>
        </axis>
      </joint>
      <joint name='arm_joint_4' type='revolute'>
        <pose>0 0 0 0 -0 0</pose>
        <parent>arm_link_3</parent>
        <child>arm_link_4</child>
        <axis>
          <dynamics>
            <damping>1</damping>
            <friction>0</friction>
            <spring_reference>0</spring_reference>
            <spring_stiffness>0</spring_stiffness>
          </dynamics>
          <limit>
            <lower>0</lower>
            <upper>3.57793</upper>
            <effort>2</effort>
            <velocity>-1</velocity>
          </limit>
          <xyz expressed_in='__model__'>-0.173648 -0.984808 0</xyz>
        </axis>
      </joint>
      <joint name='arm_joint_5' type='revolute'>
        <pose>0 0 0 0 -0 0</pose>
        <parent>arm_link_4</parent>
        <child>arm_link_5</child>
        <axis>
          <dynamics>
            <damping>1</damping>
            <friction>0</friction>
            <spring_reference>0</spring_reference>
            <spring_stiffness>0</spring_stiffness>
          </dynamics>
          <limit>
            <lower>0</lower>
            <upper>5.84685</upper>
            <effort>1</effort>
            <velocity>-1</velocity>
          </limit>
          <xyz expressed_in='__model__'>-0.360933 0.063642 -0.930418</xyz>
        </axis>
      </joint>
      <joint name='gripper_palm_joint' type='revolute'>
        <pose>0 0 0 0 -0 0</pose>
        <parent>arm_link_5</parent>
        <child>gripper_palm_link</child>
        <axis>
          <dynamics>
            <damping>0</damping>
            <friction>0</friction>
            <spring_reference>0</spring_reference>
            <spring_stiffness>0</spring_stiffness>
          </dynamics>
          <limit>
            <lower>0</lower>
            <upper>0</upper>
            <effort>0</effort>
            <velocity>0</velocity>
          </limit>
          <xyz expressed_in='__model__'>0 0 1</xyz>
        </axis>
      </joint>
      <joint name='gripper_finger_joint_l' type='prismatic'>
        <pose>0 0 0 0 -0 0</pose>
        <parent>gripper_palm_link</parent>
        <child>gripper_finger_link_l</child>
        <axis>
          <dynamics>
            <damping>1</damping>
            <friction>0</friction>
            <spring_reference>0</spring_reference>
            <spring_stiffness>0</spring_stiffness>
          </dynamics>
          <limit>
            <lower>0</lower>
            <upper>0.0115</upper>
            <effort>1</effort>
            <velocity>-1</velocity>
          </limit>
          <xyz expressed_in='__model__'>0.367852 0.926495 -0.079325</xyz>
        </axis>
      </joint>
      <joint name='gripper_finger_joint_r' type='prismatic'>
        <pose>0 0 0 0 -0 0</pose>
        <parent>gripper_palm_link</parent>
        <child>gripper_finger_link_r</child>
        <axis>
          <dynamics>
            <damping>1</damping>
            <friction>0</friction>
            <spring_reference>0</spring_reference>
            <spring_stiffness>0</spring_stiffness>
          </dynamics>
          <limit>
            <lower>0</lower>
            <upper>0.0115</upper>
            <effort>1</effort>
            <velocity>-1</velocity>
          </limit>
          <xyz expressed_in='__model__'>-0.367852 -0.926495 0.079325</xyz>
        </axis>
      </joint>
      <joint name='base_laser_front_hokuyo_urg04_laser_joint' type='revolute'>
        <pose>0 0 0 0 -0 0</pose>
        <parent>base_link</parent>
        <child>base_laser_front_link</child>
        <axis>
          <dynamics>
            <damping>0</damping>
            <friction>0</friction>
            <spring_reference>0</spring_reference>
            <spring_stiffness>0</spring_stiffness>
          </dynamics>
          <limit>
            <lower>0</lower>
            <upper>0</upper>
            <effort>0</effort>
            <velocity>0</velocity>
          </limit>
          <xyz expressed_in='__model__'>0 0 1</xyz>
        </axis>
      </joint>
      <joint name='caster_joint_bl' type='revolute'>
        <pose>0 0 0 0 -0 0</pose>
        <parent>base_link</parent>
        <child>caster_link_bl</child>
        <axis>
          <dynamics>
            <damping>1</damping>
            <friction>0</friction>
            <spring_reference>0</spring_reference>
            <spring_stiffness>0</spring_stiffness>
          </dynamics>
          <limit>
            <effort>1</effort>
            <lower>-1e+16</lower>
            <upper>1e+16</upper>
          </limit>
          <xyz expressed_in='__model__'>0 0 1</xyz>
        </axis>
      </joint>
      <joint name='wheel_joint_bl' type='revolute'>
        <pose>0 0 0 0 -0 0</pose>
        <parent>caster_link_bl</parent>
        <child>wheel_link_bl</child>
        <axis>
          <dynamics>
            <damping>1</damping>
            <friction>0</friction>
            <spring_reference>0</spring_reference>
            <spring_stiffness>0</spring_stiffness>
          </dynamics>
          <limit>
            <effort>1</effort>
            <lower>-1e+16</lower>
            <upper>1e+16</upper>
          </limit>
          <xyz expressed_in='__model__'>0 1 0</xyz>
        </axis>
      </joint>
      <joint name='caster_joint_br' type='revolute'>
        <pose>0 0 0 0 -0 0</pose>
        <parent>base_link</parent>
        <child>caster_link_br</child>
        <axis>
          <dynamics>
            <damping>1</damping>
            <friction>0</friction>
            <spring_reference>0</spring_reference>
            <spring_stiffness>0</spring_stiffness>
          </dynamics>
          <limit>
            <effort>1</effort>
            <lower>-1e+16</lower>
            <upper>1e+16</upper>
          </limit>
          <xyz expressed_in='__model__'>0 0 1</xyz>
        </axis>
      </joint>
      <joint name='wheel_joint_br' type='revolute'>
        <pose>0 0 0 0 -0 0</pose>
        <parent>caster_link_br</parent>
        <child>wheel_link_br</child>
        <axis>
          <dynamics>
            <damping>1</damping>
            <friction>0</friction>
            <spring_reference>0</spring_reference>
            <spring_stiffness>0</spring_stiffness>
          </dynamics>
          <limit>
            <effort>1</effort>
            <lower>-1e+16</lower>
            <upper>1e+16</upper>
          </limit>
          <xyz expressed_in='__model__'>0 1 0</xyz>
        </axis>
      </joint>
      <joint name='caster_joint_fl' type='revolute'>
        <pose>0 0 0 0 -0 0</pose>
        <parent>base_link</parent>
        <child>caster_link_fl</child>
        <axis>
          <dynamics>
            <damping>1</damping>
            <friction>0</friction>
            <spring_reference>0</spring_reference>
            <spring_stiffness>0</spring_stiffness>
          </dynamics>
          <limit>
            <effort>1</effort>
            <lower>-1e+16</lower>
            <upper>1e+16</upper>
          </limit>
          <xyz expressed_in='__model__'>0 0 1</xyz>
        </axis>
      </joint>
      <joint name='wheel_joint_fl' type='revolute'>
        <pose>0 0 0 0 -0 0</pose>
        <parent>caster_link_fl</parent>
        <child>wheel_link_fl</child>
        <axis>
          <dynamics>
            <damping>1</damping>
            <friction>0</friction>
            <spring_reference>0</spring_reference>
            <spring_stiffness>0</spring_stiffness>
          </dynamics>
          <limit>
            <effort>1</effort>
            <lower>-1e+16</lower>
            <upper>1e+16</upper>
          </limit>
          <xyz expressed_in='__model__'>0 1 0</xyz>
        </axis>
      </joint>
      <joint name='caster_joint_fr' type='revolute'>
        <pose>0 0 0 0 -0 0</pose>
        <parent>base_link</parent>
        <child>caster_link_fr</child>
        <axis>
          <dynamics>
            <damping>1</damping>
            <friction>0</friction>
            <spring_reference>0</spring_reference>
            <spring_stiffness>0</spring_stiffness>
          </dynamics>
          <limit>
            <effort>1</effort>
            <lower>-1e+16</lower>
            <upper>1e+16</upper>
          </limit>
          <xyz expressed_in='__model__'>0 0 1</xyz>
        </axis>
      </joint>
      <joint name='wheel_joint_fr' type='revolute'>
        <pose>0 0 0 0 -0 0</pose>
        <parent>caster_link_fr</parent>
        <child>wheel_link_fr</child>
        <axis>
          <dynamics>
            <damping>1</damping>
            <friction>0</friction>
            <spring_reference>0</spring_reference>
            <spring_stiffness>0</spring_stiffness>
          </dynamics>
          <limit>
            <effort>1</effort>
            <lower>-1e+16</lower>
            <upper>1e+16</upper>
          </limit>
          <xyz expressed_in='__model__'>0 1 0</xyz>
        </axis>
      </joint>
      <joint name='plate_joint' type='revolute'>
        <parent>base_link</parent>
        <child>plate_link</child>
        <axis>
          <dynamics>
            <damping>0</damping>
            <friction>0</friction>
            <spring_reference>0</spring_reference>
            <spring_stiffness>0</spring_stiffness>
          </dynamics>
          <limit>
            <lower>0</lower>
            <upper>0</upper>
            <effort>0</effort>
            <velocity>0</velocity>
          </limit>
          <xyz expressed_in='__model__'>0 0 1</xyz>
        </axis>
      </joint>
      <static>0</static>
    </model>
    <model name='husky'>
      <pose>8.67319 0.891169 0.5 0 -0 0</pose>
      <link name='base_link'>
        <collision name='collision'>
          <pose>0 0 0.1 0 -0 0</pose>
          <geometry>
            <box>
              <size>1.0074 0.5709 0.2675</size>
            </box>
          </geometry>
          <max_contacts>10</max_contacts>
          <surface>
            <contact>
              <ode/>
            </contact>
            <bounce/>
            <friction>
              <torsional>
                <ode/>
              </torsional>
              <ode/>
            </friction>
          </surface>
        </collision>
        <inertial>
          <mass>33.855</mass>
          <pose>-0.085613 -0.00084 0.238145 0 -0 0</pose>
          <inertia>
            <ixx>2.2343</ixx>
            <ixy>-0.023642</ixy>
            <ixz>0.275174</ixz>
            <iyy>3.42518</iyy>
            <iyz>0.00239624</iyz>
            <izz>2.1241</izz>
          </inertia>
        </inertial>
        <visual name='base'>
          <pose>0 0 0 0 -0 0</pose>
          <geometry>
            <mesh>
              <uri>model://husky/meshes/base_link.stl</uri>
            </mesh>
          </geometry>
          <material>
            <script>
              <name>Gazebo/FlatBlack</name>
              <uri>__default__</uri>
            </script>
          </material>
        </visual>
        <visual name='top_plate'>
          <pose>0 0 0 0 -0 0</pose>
          <geometry>
            <mesh>
              <uri>model://husky/meshes/top_plate.stl</uri>
            </mesh>
          </geometry>
          <material>
            <script>
              <name>Gazebo/Yellow</name>
              <uri>__default__</uri>
            </script>
          </material>
        </visual>
        <visual name='front_bumper'>
          <pose>0.47 0 0.091 0 -0 0</pose>
          <geometry>
            <mesh>
              <uri>model://husky/meshes/bumper.stl</uri>
            </mesh>
          </geometry>
          <material>
            <script>
              <name>Gazebo/FlatBlack</name>
              <uri>__default__</uri>
            </script>
          </material>
        </visual>
        <visual name='rear_bumper'>
          <pose>-0.47 0 0.091 0 -0 3.141</pose>
          <geometry>
            <mesh>
              <uri>model://husky/meshes/bumper.stl</uri>
            </mesh>
          </geometry>
          <material>
            <script>
              <name>Gazebo/FlatBlack</name>
              <uri>__default__</uri>
            </script>
          </material>
        </visual>
        <visual name='user_rail'>
          <pose>0.272 0 0.245 0 -0 0</pose>
          <geometry>
            <mesh>
              <uri>model://husky/meshes/user_rail.stl</uri>
            </mesh>
          </geometry>
          <material>
            <script>
              <name>Gazebo/Grey</name>
              <uri>__default__</uri>
            </script>
          </material>
        </visual>
        <self_collide>0</self_collide>
        <enable_wind>0</enable_wind>
        <kinematic>0</kinematic>
      </link>
      <link name='back_left_wheel'>
        <pose>-0.256 0.285475 0.035 0 -0 0</pose>
        <inertial>
          <mass>2.6357</mass>
          <pose>0 0 0 0 -0 0</pose>
          <inertia>
            <ixx>0.0246688</ixx>
            <ixy>0</ixy>
            <ixz>0</ixz>
            <iyy>0.0246688</iyy>
            <iyz>0</iyz>
            <izz>0.0441058</izz>
          </inertia>
        </inertial>
        <collision name='back_left_wheel_collision'>
          <pose>0 0 0 -1.5707 0 0</pose>
          <geometry>
            <cylinder>
              <radius>0.17775</radius>
              <length>0.1143</length>
            </cylinder>
          </geometry>
          <surface>
            <friction>
              <ode>
                <mu>100000</mu>
                <mu2>100000</mu2>
                <slip1>0</slip1>
                <slip2>0</slip2>
              </ode>
              <torsional>
                <ode/>
              </torsional>
            </friction>
            <contact>
              <ode/>
            </contact>
            <bounce/>
          </surface>
          <max_contacts>10</max_contacts>
        </collision>
        <visual name='back_left_wheel'>
          <pose>0 0 0 -3.14159 0 0</pose>
          <geometry>
            <mesh>
              <uri>model://husky/meshes/wheel.stl</uri>
            </mesh>
          </geometry>
          <material>
            <script>
              <name>Gazebo/Grey</name>
              <uri>__default__</uri>
            </script>
          </material>
        </visual>
        <self_collide>0</self_collide>
        <enable_wind>0</enable_wind>
        <kinematic>0</kinematic>
      </link>
      <joint name='back_left_joint' type='revolute'>
        <parent>base_link</parent>
        <child>back_left_wheel</child>
        <axis>
          <xyz expressed_in='__model__'>0 1 0</xyz>
          <limit>
            <lower>-1e+16</lower>
            <upper>1e+16</upper>
          </limit>
          <dynamics>
            <spring_reference>0</spring_reference>
            <spring_stiffness>0</spring_stiffness>
          </dynamics>
        </axis>
        <physics>
          <ode>
            <limit>
              <cfm>0</cfm>
              <erp>0.9</erp>
            </limit>
          </ode>
        </physics>
      </joint>
      <link name='back_right_wheel'>
        <pose>-0.256 -0.285475 0.035 0 -0 0</pose>
        <inertial>
          <mass>2.6357</mass>
          <pose>0 0 0 0 -0 0</pose>
          <inertia>
            <ixx>0.0246688</ixx>
            <ixy>0</ixy>
            <ixz>0</ixz>
            <iyy>0.0246688</iyy>
            <iyz>0</iyz>
            <izz>0.0441058</izz>
          </inertia>
        </inertial>
        <collision name='back_right_wheel_collision'>
          <pose>0 0 0 -1.5707 0 0</pose>
          <geometry>
            <cylinder>
              <radius>0.17775</radius>
              <length>0.1143</length>
            </cylinder>
          </geometry>
          <surface>
            <friction>
              <ode>
                <mu>100000</mu>
                <mu2>100000</mu2>
                <slip1>0</slip1>
                <slip2>0</slip2>
              </ode>
              <torsional>
                <ode/>
              </torsional>
            </friction>
            <contact>
              <ode/>
            </contact>
            <bounce/>
          </surface>
          <max_contacts>10</max_contacts>
        </collision>
        <visual name='back_right_wheel'>
          <pose>0 0 0 -3.14159 0 0</pose>
          <geometry>
            <mesh>
              <uri>model://husky/meshes/wheel.stl</uri>
            </mesh>
          </geometry>
          <material>
            <script>
              <name>Gazebo/Grey</name>
              <uri>__default__</uri>
            </script>
          </material>
        </visual>
        <self_collide>0</self_collide>
        <enable_wind>0</enable_wind>
        <kinematic>0</kinematic>
      </link>
      <joint name='back_right_joint' type='revolute'>
        <parent>base_link</parent>
        <child>back_right_wheel</child>
        <axis>
          <xyz expressed_in='__model__'>0 1 0</xyz>
          <limit>
            <lower>-1e+16</lower>
            <upper>1e+16</upper>
          </limit>
          <dynamics>
            <spring_reference>0</spring_reference>
            <spring_stiffness>0</spring_stiffness>
          </dynamics>
        </axis>
        <physics>
          <ode>
            <limit>
              <cfm>0</cfm>
              <erp>0.9</erp>
            </limit>
          </ode>
        </physics>
      </joint>
      <link name='front_left_wheel'>
        <pose>0.256 0.285475 0.035 0 -0 0</pose>
        <inertial>
          <mass>2.6357</mass>
          <pose>0 0 0 0 -0 0</pose>
          <inertia>
            <ixx>0.0246688</ixx>
            <ixy>0</ixy>
            <ixz>0</ixz>
            <iyy>0.0246688</iyy>
            <iyz>0</iyz>
            <izz>0.0441058</izz>
          </inertia>
        </inertial>
        <collision name='front_left_wheel_collision'>
          <pose>0 0 0 -1.5707 0 0</pose>
          <geometry>
            <cylinder>
              <radius>0.17775</radius>
              <length>0.1143</length>
            </cylinder>
          </geometry>
          <surface>
            <friction>
              <ode>
                <mu>100000</mu>
                <mu2>100000</mu2>
                <slip1>0</slip1>
                <slip2>0</slip2>
              </ode>
              <torsional>
                <ode/>
              </torsional>
            </friction>
            <contact>
              <ode/>
            </contact>
            <bounce/>
          </surface>
          <max_contacts>10</max_contacts>
        </collision>
        <visual name='front_left_wheel'>
          <pose>0 0 0 -3.14159 0 0</pose>
          <geometry>
            <mesh>
              <uri>model://husky/meshes/wheel.stl</uri>
            </mesh>
          </geometry>
          <material>
            <script>
              <name>Gazebo/Grey</name>
              <uri>__default__</uri>
            </script>
          </material>
        </visual>
        <self_collide>0</self_collide>
        <enable_wind>0</enable_wind>
        <kinematic>0</kinematic>
      </link>
      <joint name='front_left_joint' type='revolute'>
        <parent>base_link</parent>
        <child>front_left_wheel</child>
        <axis>
          <xyz expressed_in='__model__'>0 1 0</xyz>
          <limit>
            <lower>-1e+16</lower>
            <upper>1e+16</upper>
          </limit>
          <dynamics>
            <spring_reference>0</spring_reference>
            <spring_stiffness>0</spring_stiffness>
          </dynamics>
        </axis>
        <physics>
          <ode>
            <limit>
              <cfm>0</cfm>
              <erp>0.9</erp>
            </limit>
          </ode>
        </physics>
      </joint>
      <link name='front_right_wheel'>
        <pose>0.256 -0.285475 0.035 0 -0 0</pose>
        <inertial>
          <mass>2.6357</mass>
          <pose>0 0 0 0 -0 0</pose>
          <inertia>
            <ixx>0.0246688</ixx>
            <ixy>0</ixy>
            <ixz>0</ixz>
            <iyy>0.0246688</iyy>
            <iyz>0</iyz>
            <izz>0.0441058</izz>
          </inertia>
        </inertial>
        <collision name='front_right_wheel_collision'>
          <pose>0 0 0 -1.5707 0 0</pose>
          <geometry>
            <cylinder>
              <radius>0.17775</radius>
              <length>0.1143</length>
            </cylinder>
          </geometry>
          <surface>
            <friction>
              <ode>
                <mu>100000</mu>
                <mu2>100000</mu2>
                <slip1>0</slip1>
                <slip2>0</slip2>
              </ode>
              <torsional>
                <ode/>
              </torsional>
            </friction>
            <contact>
              <ode/>
            </contact>
            <bounce/>
          </surface>
          <max_contacts>10</max_contacts>
        </collision>
        <visual name='front_right_wheel'>
          <pose>0 0 0 -3.14159 0 0</pose>
          <geometry>
            <mesh>
              <uri>model://husky/meshes/wheel.stl</uri>
            </mesh>
          </geometry>
          <material>
            <script>
              <name>Gazebo/Grey</name>
              <uri>__default__</uri>
            </script>
          </material>
        </visual>
        <self_collide>0</self_collide>
        <enable_wind>0</enable_wind>
        <kinematic>0</kinematic>
      </link>
      <joint name='front_right_joint' type='revolute'>
        <parent>base_link</parent>
        <child>front_right_wheel</child>
        <axis>
          <xyz expressed_in='__model__'>0 1 0</xyz>
          <limit>
            <lower>-1e+16</lower>
            <upper>1e+16</upper>
          </limit>
          <dynamics>
            <spring_reference>0</spring_reference>
            <spring_stiffness>0</spring_stiffness>
          </dynamics>
        </axis>
        <physics>
          <ode>
            <limit>
              <cfm>0</cfm>
              <erp>0.9</erp>
            </limit>
          </ode>
        </physics>
      </joint>
      <plugin name='husky_diff_controller' filename='libhusky_gazebo_plugins.so'>
        <alwaysOn>1</alwaysOn>
        <updateRate>100.0</updateRate>
        <backLeftJoint>back_left_joint</backLeftJoint>
        <backRightJoint>back_right_joint</backRightJoint>
        <frontLeftJoint>front_left_joint</frontLeftJoint>
        <frontRightJoint>front_right_joint</frontRightJoint>
        <wheelSeparation>0.5709</wheelSeparation>
        <wheelDiameter>0.3555</wheelDiameter>
        <torque>35</torque>
      </plugin>
    </model>
  </world>
</sdf>
